Workbook

Sheet 🧠 CLAUDE CONTEXT
A1: 🧠 CLAUDE CONTEXT — Mémoire de session · Auto-généré · Ne pas modifier manuellement
A2: Uploader ce fichier à chaque session → Claude lit ce bloc en premier et reprend le contexte complet instantanément
A4: 📋 DERNIÈRE SESSION
A5: Version fichier | B5: v63-S39 | C5: Mis à jour automatiquement par Claude en fin de session
A6: Date session | B6: 13 mars 2026 | C6: HNE · Nunavik
A7: Prochaine session | B7: S36 — xlsx v59 + dashboard v16 + CLAUDE.md + data.json
A9: 📊 ÉTAT PORTFOLIO · 13 MARS 2026
A10: Total CAD | B10: ~$89,674 CAD (XEQT 100u confirmé · data.json 8h55 +$3,993) | C10: ATH: $87,252 · 10 mars 2026
A11: P&L ouvert | B11: +$13,469 CAD estimé · recalcul S36 avec data.json
A12: Coût de base | B12: $76,054.68
A13: TFSA | B13: $68,137 | C13: Dépôts: $51,500 · P&L +34.37%
A14: FHSA | B14: $18,772 CAD · XEQT 115u (100 FHSA + 25 TFSA) · VFV 16u FHSA | C14: XEQT 100u @$39.93 + VFV 16u · Objectif: $40,000
A15: REER | B15: $2,765 | C15: SCHD 64.3053u + JEPI 1u + cash $1.26 CAD
A16: USD/CAD | B16: 1.3702 | C16: Dynamique — fallback config
A17: Positions actives | B17: 40 — TFSA 26 · FHSA 12 · REER 2 | C17: TFSA 26 · FHSA 12 · REER 2
A18: USD exposition | B18: ~62% | C18: ✅ Sous seuil 65%
A20: 🔴 ACTIONS OUVERTES — PRIORITÉ S36
A21: 🔴 URGENT | B21: EQ Bank HISA — ouvrir compte | C21: $0 actuel → cible $15,000 · $1,500/mois automatique
A22: 🔴 URGENT | B22: Bénéficiaires Questrade | C22: TFSA + FHSA + REER sans bénéficiaires · ~$87K non protégé · 5 min
A23: 🔴 URGENT | B23: Automatiser $5,000/mois | C23: Avant 15 avril · REER $2K + FHSA $1K + TFSA $500 + EQ Bank $1.5K
A24: 🟡 IMPORTANT | B24: Post-BdC 18 mars → ZRE+XIC+VDU vers VFV.TO | C24: ~$1,878 à recycler de T4 vers T1 dans TFSA
A25: 🟡 IMPORTANT | B25: FHSA T4 trop élevé → recycler vers VFV.TO | C25: REI+SRU+XIC+XEI FHSA = $4,752 T4 · compte double exonération = max T1
A26: 📅 CALENDRIER | B26: Verdicts J+30 → 11 avril | C26: AVGO · SMH · GEV · SCHD · PLZ.UN · calculer alpha vs VFV.TO
A28: ✅ ACCOMPLI — S34-S35 · 13 MARS 2026
A29: ✅ Trade | B29: Research marché exhaustif mars 2026 complété (macro Iran/Fed/TSX + top 15 actions + 15 ETFs) | C29: TFSA qty=0 confirmé
A30: ✅ Trade | B30: XEQT.TO 100u @$39.93 FHSA exécuté 15:06:55 ET · décision modifiée 50/50 → 100% XEQT suite Research | C30: 13 mars 2026
A31: ✅ Dashboard | B31: portfolio_dashboard_v16.html | C31: Tickers cliquables · tri interactif · graphiques Chart.js jouables · 30 factsheets
A32: ✅ Dashboard | B32: xlsx v63-S39 | C32: Cerveau multi-piliers · CLAUDE CONTEXT · APPRENTISSAGE · CORPS · CULTURE · PROJET DE VIE
A33: ✅ Système | B33: CLAUDE CONTEXT intégré dans xlsx | C33: Onglet auto-généré · 0 upload manuel requis
A35: 🧠 DÉCISIONS & RAISONNEMENTS CLÉS
A36: Plan cotisation | B36: $5,000/mois confirmé S16 | C36: REER $2K + FHSA $1K + TFSA $500 + EQ Bank $1.5K · surplus libre $1,768/mois
A37: Snowball REER | B37: $2K/mois SCHD → ~$1,060 ARC remboursé | C37: 52.98% taux marginal Québec · mécanique clé
A38: FI objectif | B38: $2.1M = plancher · jamais plafond | C38: Liberté & optionalité · pas un chiffre fixe
A39: Maison 2030+ | B39: RAP $60K (REER) + FHSA $40K = $100K mise de fonds | C39: Solo · timeline révisée de 2028 à 2030+
A40: Psychologie | B40: Buy-the-dip T1 = conviction forte | C40: COVID 2020 ancre · -30%+ = ACHETER PLUS · frein = liquidités + timing
A42: ⚠️ RÈGLES ABSOLUES — Claude applique sans exception
A43: 🚫 JAMAIS | B43: Vendre T.TO ou MFC.TO dans TFSA | C43: Room de contribution perdu à jamais si vendu
A44: 🚫 JAMAIS | B44: Recréer le xlsx de zéro | C44: Toujours load_workbook — 2133 formules à préserver
A45: 🚫 JAMAIS | B45: Modifier xlsx sans autorisation explicite de Hey | C45: Demander "go" avant tout code
A46: ✅ TOUJOURS | B46: Vérifier room FHSA avant cotisation | C46: Room 2026 restant: ~$13,700
...

Sheet 🚀 DÉMARRAGE
A1: 🚀 DÉMARRAGE CLAUDE · Portefeuille FI 2026 · v63-S39 · 13 mars 2026 · Glisser ce fichier → Session démarre automatiquement | B1: 🚀 DÉMARRAGE CLAUDE · Portefeuille FI 2026 · v63-S39 · 13 mars 2026
B2: "Lis du haut vers le bas → web search → ta 1ʳᵉ réponse = les 3 points les plus importants. Zéro question de contexte."
A4: 📊 SNAPSHOT PORTFOLIO · Soir 13 mars 2026 · Source: Questrade confirmé
B5: COMPTE | C5: VALEUR CAD | D5: P&L $ | E5: P&L % | F5: INVESTI | G5: ACTIONS URGENTES
A6: TFSA 📈 | B6: ='📈 PORTEFEUILLE'!C8 | C6: 68072.95 | D6: ='📈 PORTEFEUILLE'!G8 | E6: ='📈 PORTEFEUILLE'!E8 | F6: VFV.TO $1,000/mois · room $13,700 restant
A7: FHSA 🏠 | B7: ='📈 PORTEFEUILLE'!C9 | C7: 18816.32 | D7: ='📈 PORTEFEUILLE'!G9 | E7: ='📈 PORTEFEUILLE'!E9 | F7: SCHD ✅ 64.3053u · +$1,060/mois ARC · Prochain: $2,000 le 12 mars
A8: REER ❄️ | B8: ='📈 PORTEFEUILLE'!C10 | C8: 2798.09 | D8: ='📈 PORTEFEUILLE'!G10 | E8: ='📈 PORTEFEUILLE'!E10 | F8: ✅ SCHD $2,000 REER exécuté · 64.3053u @ $30.80
A9: ▼ TOTAL | B9: ='📈 PORTEFEUILLE'!C11 | C9: 89687.36 | D9: 16572.89 | E9: 0.1762
A10: 📊 Ref YTD | B10: $74,290 CAD (est. 1 jan 2026) | E10: VFV YTD: -1.57% | G10: Alpha: ⬜ Calculer
A11: 📈 Perf 1 an
A14: 🚨 ACTIONS URGENTES · Coût d'inaction réel chaque jour
B15: # | C15: ACTION | E15: ÉCHÉANCE | F15: STATUT
B16: ✅ FAIT — SCHD $2,000 REER exécuté 12 mars · 64.3053u confirmés | C16: SCHD $2,000 REER → 12 mars 9h30 HNE | E16: +$1,060/mois ARC (52.98%×$2K) | F16: 12 mars AM | G16: ✅ EXÉCUTÉ — 64.3053u confirmé Questrade
B17: 🟡 EN COURS — Ouvrir EQ Bank + virer $1,500 dès prochaine paie cette semaine | C17: 10 mois → $15,000 atteint · AVANT Questrade dès que paie rentre | E17: Risque opérationnel éliminé | F17: ASAP | G17: PAS OUVERT
B18: 🟡3 | C18: ZRE+XIC+VDU TFSA ~$1,878 → T1 | E18: ~$1,878 T4→T1 + exposition IA+ | F18: Post-BdC 18 mars | G18: EN ATTENTE
B20: 📅5 | E20: Calendrier macro + earnings
A22: ⚡ PROTOCOLE SESSION · Dans l'ordre · 10 minutes max · voir Section 11 pour détail
A23: 🔥 1 | B23: Aspects #1+#2 uploadés · #3 taux USD/CAD → CONFIG!B3 · #4 trades faits | E23: CRITIQUE · Section 14 pour guide uploads
A24: 🔥 2 | B24: VALIDATION → ÉTAT GLOBAL = 🟢 · si 🔴 → corriger avant de continuer | E24: 2 min max
A25: 🔥 3 | B25: Snapshot → #5 cash · #6 cotisations YTD · #12 pending session précédente | E25: Confirmer positions + buying power
A26: ⭐ 4 | B26: Dire: #8 intention · #9 trades envisagés · #13 calendrier · #14 dividendes | E26: 3 phrases · voir template Section 11
A27: ⭐ 5 | B27: Claude applique: #7 macro (web search auto) · #11 benchmark · R1→R13 | E27: Automatique · aucune action
A29: 🎯 PLAN D'EXÉCUTION IMMÉDIAT · 3 actions · Chaque jour de retard = argent perdu
A30: 🔴 ACTION #1 — SCHD $2,000 REER · DEMAIN 12 mars · 9h30 HNE pile à l'ouverture
A31: ÉTAPE | B31: Ouvrir Questrade → REER #52924767 → Acheter SCHD
A32: MONTANT | B32: $2,000 CAD ordre → ~$1,475 USD au taux ~1.3559
A33: ORDRE
A34: IMPACT IMMÉDIAT | B34: +$1,060/mois ARC (remboursé en ~6 semaines après déclaration)
A35: COÛT INACTION
A36: APRÈS | B36: MAJ CONFIG!B34 (REER YTD: 0→2000) + noter dans JOURNAL DÉCISIONS
A38: 🔴 ACTION #2 — EQ Bank HISA $15,000 · Cette semaine · ~20 min en ligne
A39: SITE | B39: eqbank.ca → Ouvrir un compte épargne → taux ~4.0% (confirmer live)
A40: VIREMENT
A41: RÔLE | B41: Fonds urgence exclusivement · ne pas investir · ne pas toucher
A42: POURQUOI | B42: Risque opérationnel #1 — si urgence médicale/équipement/voiture = zéro stress
A43: RENDEMENT
A44: APRÈS | B44: MAJ CONFIG!B25 (HISA → $15,000) + mettre à jour ALERTES section fonds urgence
A46: 📅 ACTION #3 — Verdicts J+30 · 11 avril 2026 · Mettre une alarme maintenant
A47: DATE EXACTE | B47: 11 avril 2026 — mettre alarme téléphone MAINTENANT
A48: DURÉE | B48: ~30 min · ouvrir Questrade · noter prix de chaque ticker du 11 mars
...

Sheet 🧠 PROFIL
B1: 🧠 PROFIL INVESTISSEUR · Source de vérité sur TOI · Mis à jour annuellement
B2: Ce document = la mémoire de qui tu es en tant qu'investisseur. Claude le lit en priorité à chaque session.
B4: 👤 IDENTITÉ FINANCIÈRE
B5: Âge actuel | C5: =CONFIG!B4 | D5: ←auto | E5: ans
B6: Revenu brut annuel | C6: 140000 | D6: ⬜ Confirmer avec T4 2025 | E6: CAD
B7: Revenu NET estimé /mois | C7: 7950 | D7: ← $3,000 × 26 ÷ 12 + $1,450 prime Nunavik · Confirmé S16 | E7: CAD/mois
B8: Dépenses fixes /mois | C8: 1182 | D8: Épicerie $400 + Tél $110 + Voiture $275 + Ass.auto $100 + Ass.moto $80 + Essence $50 + Abo $25 + Loisirs $50 + Voyages $42 + Vêt $50 · MAJ S16 | E8: CAD/mois
B9: Capacité épargne réelle /mois | C9: =C7-C8 | D9: ← Calculé automatiquement | E9: CAD/mois
B10: Contributions investissement | C10: 5000 | D10: REER $2K + FHSA $1K + TFSA $500 + EQ Bank $1,500 · Plan confirmé S16 | E10: CAD/mois
B11: Surplus non investi /mois | C11: =C9-C10 | D11: ← Tampon / extra / imprévus | E11: CAD/mois
B12: Taux marginal QC | C12: =CONFIG!B11 | D12: ←auto CONFIG | E12: %
B13: Zone géographique | C13: Nunavik QC | D13: Avantages: logement+bouffe gratuits · Désavantage: isolement, mobilité réduite
B14: Situation couple | C14: En couple | D14: Finances 100% séparées · achat maison solo prévu
B15: Régime retraite employeur | C15: =CONFIG!B30 | D15: ←auto CONFIG
B17: 🎯 PROFIL DE RISQUE · Réponses honnêtes · Ne pas idéaliser
B18: Tolérance drawdown maximale | C18: -30% à -40% | D18: Basé sur comportement COVID 2020 : achat agressif à -35%. Au-delà de -40% sur portfolio total = zone inconnue. | E18: 🟠 AGRESSIF
B19: Réaction prouvée en crise | C19: ACHAT MASSIF | D19: COVID mars 2020 : positions achetées pendant le crash. Comportement documenté, pas théorique. | E19: ✅ VALIDÉ
B20: Scénario qui te ferait vraiment vendre | C20: ⬜ À documenter | D20: Ex: perte emploi simultanée + drawdown -40% + urgence médicale. Quel est ton vrai point de rupture ? | E20: ⬜ DÉFINIR
B21: Horizon d'investissement réel | C21: 2043 (FI) + 20 ans après | D21: ~17 ans jusqu'à FI potentiel, puis 30+ ans de décaissement. Horizon total = 47 ans. | E21: ✅ LONG TERME
B22: Acceptation volatilité mensuelle | C22: ±$5,000-8,000 CAD | D22: Portfolio $87K × 8% volatilité mensuelle typique ≈ ±$7K. Confortable ? | E22: ⬜ CONFIRMER
B23: Biais comportementaux identifiés | C23: Buy-the-dip fort · FOMO possible sur IA | D23: Forces: discipline achat en crise. Risques: surpondération IA sans discipline de seuil. | E23: ⚠️ SURVEILLER
B24: Score risque objectif (1-10) | C24: 8 | D24: 8/10 = profil agressif orienté croissance. Justifié par horizon 17+ ans et épargne high-rate. | E24: 🔴 AGRESSIF
B26: 🆘 STRESS-TEST · Que se passe-t-il si... · Plan B pour chaque scénario
B27: SCÉNARIO | C27: IMPACT ESTIMÉ | D27: PLAN B ACTIVÉ | E27: SEUIL DÉCLENCHEUR
B28: Perte d'emploi 12 mois | C28: Zéro revenu · dépenses fixes $700/mois seulement · portfolio intact | D28: EQ Bank $15K (7 mois) · stop contributions · vendre ZRE+XIC+VDU T4 si besoin | E28: Chômage confirmé
B29: Marché -30% (ex: récession 2025) | C29: Portfolio $87K → ~$61K · P&L TFSA effacé | D29: ACHAT AGRESSIF T1 · doubler contributions si cash dispo · NE PAS vendre | E29: S&P500 -20% depuis ATH
B30: Marché -40% (ex: 2008-09) | C30: Portfolio $87K → ~$52K · AVGO/SMH/GEV potentiellement -50% | D30: Même plan: acheter · vérifier qu'aucun titre n'est en danger fondamental · tenir | E30: VIX > 40
B31: Invalidité permanente | C31: ✅ Couverture COMPLÈTE employeur · Assurance vie: employeur + privée ✅ | D31: 🔴 Bénéficiaires TFSA/REER/FHSA NON DÉSIGNÉS — ACTION: Questrade → Mon compte → Bénéficiaires | E31: Diagnostic médical
B32: Décès (planification successorale) | C32: TFSA → conjoint/bénéficiaire tax-free · REER → succession imposable | D32: ⬜ DÉFINIR: bénéficiaires TFSA/REER/FHSA · testament à jour | E32: N/A — prévenir maintenant
B33: Taux hypothécaires > 7% en 2030 | C33: Paiement mensuel $400K @7% = $2,798/mois vs $1,222 @4.5% | D33: Revoir décision maison · attendre baisse taux · augmenter mise de fonds | E33: Taux 5 ans > 6%
B35: 📉 INFLATION · $2.1M en 2043 ≠ $2.1M aujourd'hui · Impact réel modélisé
B36: Taux inflation hypothèse | C36: 0.025 | D36: Inflation Canada historique ~2.0-2.5%. BdC cible = 2%.
B37: Années jusqu'à FI (Scénario B) | C37: 21 | D37: 2026 → 2047 (FI 55 ans, confirmé S16)
B38: Objectif FI nominal ($) | C38: =CONFIG!B20 | D38: ←auto CONFIG
B39: ⚠️ Objectif FI RÉEL ajusté inflation | C39: =C38*(1+C36)^C37 | D39: ← En dollars 2043 pour MÊME pouvoir d'achat qu'aujourd'hui
B40: Écart vs objectif nominal | C40: =C39-C38 | D40: ← Combien il manque par rapport à $2.1M nominal · Ajuster la cible FI en conséquence
B41: Revenu mensuel équivalent en 2043 | C41: =C38*(1+C36)^C37*0.04/12 | D41: ← Règle 4% sur objectif ajusté = revenu mensuel réel équivalent à $7K/mois 2026
B43: 💎 PATRIMOINE NET TOTAL · Au-delà du portfolio · Bilan complet
B44: ACTIF | C44: VALEUR CAD | D44: NOTE | E44: LIQUIDITÉ
B45: TFSA | C45: ='📈 PORTEFEUILLE'!L44 | D45: ←auto · Investissement long terme | E45: 🔴 Intouchable
...

Sheet 📓 JOURNAL DÉCISIONS
B1: 📓 JOURNAL DÉCISIONS · Apprentissage continu · Ne jamais répéter la même erreur deux fois
B2: "Chaque décision documentée = Claude apprend. Résultat J+30 obligatoire. Dans 6 mois ce journal = meilleur atout."
A4: 📋 LOG DÉCISIONS · Saisir après chaque transaction ou décision importante
B5: DATE | C5: TICKER | D5: COMPTE | E5: ACTION | F5: MONTANT | G5: PRIX | H5: RATIONALE | I5: RÉSULTAT J+30 | J5: DELTA % | K5: LEÇON | L5: VERDICT
B6: 2026-03-11 | C6: AVGO | D6: TFSA | E6: ACHETÉ | F6: ~$462 | G6: $340.95 | H6: Soir · buying power settle · 1u fractionnel · DCA opportuniste | I6: ⬜ À remplir 11 avr 2026
B7: 2026-03-11 | C7: GEV | D7: TFSA | E7: ACHETÉ | F7: ~$314 | G7: $845.53 | H7: Soir · fractionnel · énergie IA · position stratégique renforcée | I7: ⬜ À remplir 11 avr 2026
B8: 2026-03-11 | C8: SMH | D8: TFSA | E8: ACHETÉ | F8: ~$2,715 | G8: $400.33 | H8: 13h55 · T4→T1 · semi-conducteurs · dip session · +5u | I8: ⬜ À remplir 11 avr 2026
B9: 2026-03-11 | C9: AVGO | D9: TFSA | E9: ACHETÉ | F9: ~$2,772 | G9: $340.65 | H9: 13h34 · T4→T1 · IA chips · redéploiement PLZ.UN · +6u | I9: ⬜ À remplir 11 avr 2026
B10: 2026-03-11 | C10: GEV | D10: TFSA | E10: ACHETÉ | F10: ~$1,144 | G10: $844.18 | H10: 13h37 · T4→T1 · énergie IA infrastructure · +1u | I10: ⬜ À remplir 11 avr 2026
B11: 2026-03-11 | C11: REI.UN.TO | D11: TFSA | E11: VENDU | F11: $6,315 | G11: $19.02 | H11: 13h54 · T4→T1 · REIT résidentiel sous-pression taux élevés | I11: ✅ Capital redéployé SMH | J11: REITs TFSA → dilution naturelle confirmée
B12: 2026-03-11 | C12: PLZ.UN.TO | D12: TFSA | E12: VENDU | F12: $4,094 | G12: $4.26 | H12: 13h33 · T4→T1 · en gain +17% · REIT sous-performant vs T1 | I12: ✅ Capital redéployé AVGO+GEV | J12: Vendre T4 en gain = bon timing
B13: 2026-03-10 | C13: VFV.TO | D13: FHSA | E13: ACHETÉ | F13: ~$2,518 | G13: $157.38 | H13: Premier achat FHSA 2026 · double exonération fiscale · ancre CAD | I13: ⬜ À remplir 10 avr 2026
B14: 2026-03-09 | C14: AVGO | D14: TFSA | E14: ACHETÉ | F14: ~$197 | G14: $345.76 | H14: DCA mensuel fractionnel · T1 · bull case IA confirmé Q1 | I14: ⬜ À remplir 9 avr 2026
A16: ── NOUVELLES DÉCISIONS — AJOUTER ICI ──
B18: 2026-03-11 | C18: SMH ×10u | D18: TFSA | E18: ACHETÉ | F18: ~$5,434 | G18: $400.33-67 | H18: 10u en 2 tranches · diversification dip vs AVGO only | I18: ⬜ J+30 | J18: ⬜ Leçon | K18: ✅ Bon conseil · diversifier | L18: ⬜ Verdict
B19: 2026-03-09 | C19: Grande rotation | D19: TFSA | E19: MULTI | F19: ~$26K | G19: Varié | H19: Liquidation 15+ positions → T1 concentré · SESSION MAJEURE | I19: ⬜ J+30 | J19: ⬜ Leçon | K19: ✅ Rotation validée · excellent | L19: ⬜ Verdict
B20: 2026-03-09 | C20: SCHD ×2 | D20: REER | E20: ACHETÉ | F20: ~$222 USD | G20: $30.88-30.94 | H20: REER débloqué · 2 tranches · snowball ARC | I20: ⬜ J+30 | J20: ⬜ Leçon | K20: ✅ Priorité #1 · parfait | L20: ⬜ Verdict
B21: 2026-03-09
B22: 2026-03-04 | C22: ZLB.TO | D22: TFSA | E22: ACHETÉ | F22: $240 | G22: $59.97 CAD | H22: GTC · +4u Low Vol T3 · stabilité | I22: ⬜ J+30 | J22: ⬜ Leçon | K22: ⬜ À évaluer J+30 | L22: ⬜ Verdict
B23: 2026-03-03 | C23: H.TO | D23: TFSA | E23: ACHETÉ | F23: $407 | G23: $58.08 CAD | H23: GTC · +7u Hydro One T3 · utilités défensif | I23: ⬜ J+30 | J23: ⬜ Leçon | K23: ⬜ À évaluer J+30 | L23: ⬜ Verdict
B24: 2026-02-09 | C24: MFC.TO | D24: TFSA | E24: ACHETÉ | F24: $414 | G24: $51.70 CAD | H24: GTC · +8u Manulife · règle JAMAIS VENDRE active | I24: ⬜ J+30 | J24: ⬜ Leçon | K24: ⬜ À évaluer J+30 | L24: ⬜ Verdict
B25: YYYY-MM-DD | C25: TICKER | D25: CTE | E25: ACHETÉ/VENDU | F25: $ | G25: $ | H25: Pourquoi cette décision? | I25: ⬜ À remplir J+30 | J25: Leçon apprise? | K25: Conseil donné par Claude au moment du trade | L25: ⬜ Bon / Mauvais · pourquoi
B29: 💡 VERDICT J+30 : Remplir "✅ Bon · [raison]" ou "❌ Mauvais · [raison]" · Ce sont les données qui améliorent Claude session après session
A36: 🧠 PATTERNS COMPORTEMENTAUX · Reconnus par Claude · Mis à jour chaque session
B37: ID | C37: PATTERN | E37: DESCRIPTION
B38: P1 | C38: Buy the dip | E38: Achat systématique en correction · COVID playbook · jamais paniquer · AVGO -10% = achète plus
B39: P2 | C39: Timing mi-mois | E39: Liquidités arrivent mi-mois pas début · planifier achats en conséquence · pas de FOMO
B40: P3 | C40: Sessions intensives | E40: Sessions longues et profondes (vacances) vs courtes quotidiennes · adapter profondeur analyse
B41: P4 | C41: Rotation T4→T1 | E41: Rotation T4→T1 quand T4 en gain >5% · ne jamais attendre le top · agir quand gain visible
B42: P5 | C42: Fiscal first | E42: REER avant TFSA si même ticker · 52.98% retour immédiat · règle non négociable
B45: 📅 PRÉPARATION VERDICTS J+30 · À remplir le 11 avril 2026 · Évaluer chaque trade du 11 mars
B46: ⏰ Le 11 avril 2026 — ouvrir ce tableau, regarder prix Questrade de chaque ticker, remplir col I+J+K
B47: TICKER | C47: COMPTE | D47: PRIX ACHAT | E47: QTÉ | F47: DATE TRADE | G47: PRIX J+30 (11 avr) | H47: PERF 30j | I47: VERDICT CLAUDE (bon/mauvais?) | J47: LEÇON | K47: SCORE CLAUDE
B48: PLZ.UN.TO | C48: TFSA | D48: $4.26 CAD | E48: 961u | F48: 2026-03-11 | G48: ⬜ Prix J+30 | H48: VENDU | I48: ✅ Bon — T4 en gain +17% → T1 | J48: ⬜ | K48: —
B49: REI.UN.TO | C49: TFSA | D49: $19.02 CAD | E49: 332u | F49: 2026-03-11 | G49: ⬜ Prix J+30 | H49: VENDU | I49: ✅ Bon — timing pre-BdC ok | J49: ⬜ | K49: —
B50: AVGO | C50: TFSA | D50: $340.65 USD | E50: 6u | F50: 2026-03-11 | G50: ⬜ Prix J+30 | H50: ⬜ | I50: ✅ Probable — T1 IA core | J50: ⬜ | K50: ⬜
B51: GEV | C51: TFSA | D51: $844.18 USD | E51: 1u | F51: 2026-03-11 | G51: ⬜ Prix J+30 | H51: ⬜ | I51: ✅ Probable — énergie IA | J51: ⬜ | K51: ⬜
B52: SMH ×5 | C52: TFSA | D52: $400.33 USD | E52: 5u | F52: 2026-03-11 13h55 | G52: ⬜ Prix J+30 | H52: ⬜ | I52: ✅ Probable — semis dip | J52: ⬜ | K52: ⬜
B53: SMH ×5 | C53: TFSA | D53: $400.67 USD | E53: 5u | F53: 2026-03-11 14h02 | G53: ⬜ Prix J+30 | H53: ⬜ | I53: ✅ Probable — 2e tranche | J53: ⬜ | K53: ⬜
B54: AVGO soir | C54: TFSA | D54: $340.19 USD | E54: ~1u | F54: 2026-03-11 soir | G54: ⬜ Prix J+30 | H54: ⬜ | I54: ⬜ À évaluer — buying power settle | J54: ⬜ | K54: ⬜
...

Sheet 🧠 RAISONNEMENTS
A1: 🧠 RAISONNEMENTS & PSYCHOLOGIE · Le POURQUOI des décisions · Mémoire comportementale cumulée · S21
A2: 📌 Ce qui compte n'est pas QUOI tu as acheté, mais POURQUOI — et si ce pourquoi était bon. Chaque ligne = une leçon permanente.
A3: ① BIAIS PSYCHOLOGIQUES DOCUMENTÉS · Identifiés en session · Pattern recognition cumulatif
A4: BIAIS | B4: DESCRIPTION | C4: MANIFESTATION RÉELLE | D4: DÉCLENCHEUR | E4: STRATÉGIE CONTRE | F4: STATUT | G4: SESSIONS
A5: Buy-the-dip fort ✅ | B5: Achat agressif pendant corrections | C5: COVID mars 2020 : achat à -35% → retour exceptionnel. 11 mars 2026 : AVGO+SMH+GEV achetés pendant correction -3.4%. | D5: VIX > 20, S&P -5%+ depuis ATH | E5: Ancrer sur historique COVID. Calculer valeur à 10 ans. | F5: ✅ FORCE | G5: S1→S21
A6: Frein pré-achat ⚠️ | B6: Hésitation 1-3 jours avant achat même en conviction max | C6: AVGO 11 mars : 2 jours d'hésitation. Peur d'acheter trop tôt dans la correction. | D6: Incertitude marché en cours | E6: Pre-commit : décider le soir, exécuter à l'ouverture. | F6: ⚠️ ACTIF | G6: S18-S21
A7: FOMO IA possible ⚠️ | B7: Surpondération secteur IA par enthousiasme | C7: Expo IA ~35% coût base. Documenté comme risque toutes les sessions. | D7: Nouvelles IA · perf AVGO/SMH | E7: Règle absolue ≤45%. Calculer expo avant chaque achat T1 IA. | F7: ⚠️ ACTIF | G7: S14→S21
A8: Inaction sur urgences 🔴 | B8: Retarder actions simples malgré documentation répétée | C8: EQ Bank $0 après 4+ sessions. Bénéficiaires non désignés. Automatisation non faite. | D8: Sentiment que c'est moins urgent que les trades | E8: Lier action urgente à prochaine paie. Alarme téléphone. | F8: 🔴 CRITIQUE | G8: S17→S21
A9: Timing parfait ⚠️ | B9: Attendre le meilleur moment au lieu de DCA systématique | C9: Contributions non automatisées → risque timer le marché chaque mois. | D9: Volatilité · incertitude macro | E9: Automatiser le 15 de chaque mois. | F9: ⚠️ ACTIF | G9: S16→S21
A11: ② JOURNAL DES RAISONNEMENTS · Décisions clés avec le POURQUOI réel · Verdict J+30 intégré
A12: DATE | B12: TICKER | C12: ACTION | D12: ÉMOTION | E12: RAISONNEMENT RÉEL | F12: DOUTES AU MOMENT | G12: VERDICT J+30 | H12: LEÇON APPRISE
A13: 2026-03-11 | B13: AVGO | C13: 🟢 ACHETÉ | D13: Conviction + légère hésitation | E13: T1 core IA. Dip -3.4% ATH. VIX 24.6. Broadcom = quasi-monopole switch semis IA. Prix $340.65 = -15% depuis ATH. | F13: Trop tôt dans la correction? Attendre -20%? | G13: ⬜ 11 avril 2026 | H13: Hésitation = frein pré-achat actif. Conviction fondamentale = correcte. Pre-commit aurait éliminé 2 jours d'attente.
A14: 2026-03-11 | B14: SMH ×2 | C14: 🟢 ACHETÉ | D14: Conviction forte | E14: ETF semis = expo T1 sans risque titre unique. NVDA+AVGO+TSM sans concentration. VIX élevé = opportunité. | F14: Double position trop agressif? | G14: ⬜ 11 avril 2026 | H14: Double achat ETF = bon si conviction sectorielle. Moins risqué qu'un titre seul. À refaire en correction.
A15: 2026-03-11 | B15: GEV | C15: 🟢 ACHETÉ | D15: Conviction forte | E15: Infrastructure IA + énergie propre. Croissance >30%/an. Complémentaire AVBO/SMH. Small position = risque contrôlé. | F15: Valorisation élevée? Cyclique? | G15: ⬜ 11 avril 2026 | H15: Position initiée à conviction. Petite taille = entrée prudente. Accumuler si confirmation.
A16: 2026-03-11 | B16: PLZ.UN | C16: 🔴 VENDU | D16: Soulagement rationnel | E16: T4 REIT faible croissance. Libérer capital T1. Décision système, pas émotionnelle. $4,094 recyclés. | F16: Vendre en correction = bon timing? | G16: ✅ Correct | H16: Rotation T4→T1 = décision système pure. Résultat: $4,094 → AVGO+SMH+GEV. À reproduire systématiquement.
A17: 2026-03-12 | B17: SCHD | C17: 🟢 ACHETÉ | D17: Discipline pure — zéro émotion | E17: REER $2,000 → SCHD. Planifié S19. Exécuté 9h30 HNE. Snowball $1,060/mois ARC activé. | F17: Aucun — pré-commité la veille | G17: ✅ Parfait | H17: Pre-commitment = zéro hésitation. Meilleur trade = décidé avant l'ouverture. Modèle à reproduire.
A19: ③ PATTERNS RÉCURRENTS · Ce que les données révèlent sur le style décisionnel
A20: PATTERN | B20: FRÉQUENCE | C20: IMPACT | D20: VERDICT GLOBAL
A21: Buy-the-dip systématique | B21: Chaque correction >3% → achat T1 | C21: Très positif — retours supérieurs au DCA fixe 2020-2026 | D21: ✅ GARDER — C'est l'avantage compétitif principal
A22: Pre-commitment = zéro friction | B22: SCHD 12 mars = zéro hésitation vs AVGO 11 mars = 2 jours | C22: Pré-décider = exécution parfaite sans stress | D22: ✅ SYSTÉMATISER — Décider le soir, exécuter à l'ouverture
A23: Inaction sur non-trades | B23: EQ Bank, automatisation, bénéficiaires = toujours reportés | C23: Risque opérationnel cumulatif élevé | D23: 🔴 PATTERN DANGEREUX — Alarme téléphone = seule solution
A24: Validation Claude = accélérateur | B24: Sessions Claude → décisions plus rapides et plus sûres | C24: Frein pré-achat réduit de 80% | D24: ✅ CONTINUER — Valeur principale des sessions
A26: ④ RÈGLES PSYCHOLOGIQUES PERSONNELLES · Validées par expérience réelle · Gravées S21
A27: CODE | B27: NOM | C27: RÈGLE COMPLÈTE | I27: STATUT
A28: R-PSY-01 | B28: Ancre COVID 2020 | C28: En crise → rappeler : mars 2020, tu as acheté à -35% → retour exceptionnel. Même playbook toujours. | I28: ✅ Actif S1
A29: R-PSY-02 | B29: Pre-commitment obligatoire | C29: Décider le soir QUOI et COMBIEN. Exécuter à l'ouverture sans revoir la décision. | I29: ✅ Actif S20
A30: R-PSY-03 | B30: Émotion = signal, pas décision | C30: Si FOMO → reculer. Si peur → vérifier fondamentaux. Émotion = information, jamais instruction. | I30: ✅ Actif S18
A31: R-PSY-04 | B31: Urgences = alarme téléphone | C31: EQ Bank, bénéficiaires, automatisation → alarme téléphone immédiatement, pas 'tantôt'. | I31: 🔴 À implémenter
A32: R-PSY-05 | B32: Validation externe = accélérateur | C32: Partager le raisonnement avec Claude avant d'exécuter réduit le frein de 80%. | I32: ✅ Actif S16
B33: Infrastructure avant contenu | C33: Récurrent | D33: On construit de beaux outils mais les onglets restent vides | E33: ⚠️ À surveiller — nourrir le cerveau à chaque session
A35: S34 · 13 mars 2026 · DÉCISION FHSA $4,015
A36: CONTEXTE | B36: Marché en correction –4.6% depuis ATH jan 2026. Iran/pétrole. Fed bloquée. Cash FHSA $4,015 disponible.
A37: ANALYSE RÉALISÉE | B37: Top 15 actions Questrade + Top 15 ETFs canadiens analysés. Comparaison 3 options (100% VFV / 50-50 / 100% XEQT).
A38: CONCLUSION ANALYSE | B38: Aucune action individuelle appropriée pour FHSA (risque concentré, compte maison 2030). VFV.TO + XEQT.TO = meilleurs ETFs pour profil.
A39: PLAN RETENU | B39: 100% XEQT.TO · 100 unités @$39.93 · $3,993 CAD
A40: RATIONALE | B40: VFV = continuité + track record. XEQT = comble vide intl. Sharpe XEQT 1.46 > VFV 0.83. USD reste ≤65%. Deux gratuits Questrade.
A41: DEVIL'S ADVOCATE | B41: 100% VFV surperforme long terme (10+ ans) mais concentre encore plus en US dans compte déjà à 62% USD.
A42: VERDICT J+30 | B42: 13 avril 2026 · comparer XEQT.TO vs VFV.TO et vs portefeuille S&P 500 pur
A43: STATUT | B43: ✅ EXÉCUTÉ — 13 mars 2026 · 15:06:55 ET
A45: S36 · 13 mars 2026 · AUDIT SYSTÈME APPRENTISSAGE
...

Sheet 📋 MON PORTEFEUILLE
A1: 📋 MON PORTEFEUILLE · LIVE via formules · Mise à jour auto depuis 📈 PORTEFEUILLE · Trier: cliquer sur les en-têtes ▲▼
A2: ="💰 Total: $"&TEXT('📈 PORTEFEUILLE'!C11,"#,##0")&" CAD" | E2: 📈 Gain: +$14,788 (20.6%) | I2: 💵 Div/an: $1,926 CAD | L2: 📊 39 positions · TFSA + FHSA + REER | O2: 🇺🇸 USD: 44.8% 🇨🇦 CAD: 55.2%
A3: 🟢 T1 = Conviction max — Accumuler | E3: 🟡 T2 = Accumuler sélectivement | I3: 🟠 T3 = Garder, ne plus acheter | M3: ⬜ T4 = Diluer naturellement
A4: TICKER ▲▼ | B4: NOM ▲▼ | C4: TYPE ▲▼ | D4: TIER ▲▼ | E4: COMPTE ▲▼ | F4: QTÉ ▲▼ | G4: PRIX ACT ▲▼ | H4: DEV ▲▼ | I4: PRIX CAD ▲▼ | J4: VALEUR CAD ▲▼ | K4: INVESTI CAD ▲▼ | L4: GAIN $CAD ▲▼ | M4: GAIN % ▲▼ | N4: % PORT. ▲▼ | O4: YIELD % ▲▼ | P4: DIV/AN CAD ▲▼ | Q4: DIV/MOIS ▲▼ | R4: SIGNAL ▲▼
A5: ='📈 PORTEFEUILLE'!B15 | B5: ='📈 PORTEFEUILLE'!C15 | C5: ='📈 PORTEFEUILLE'!D15 | D5: ='📈 PORTEFEUILLE'!E15 | E5: ='📈 PORTEFEUILLE'!F15 | F5: ='📈 PORTEFEUILLE'!G15 | G5: ='📈 PORTEFEUILLE'!I15 | H5: ='📈 PORTEFEUILLE'!K15 | I5: ='📈 PORTEFEUILLE'!I15 | J5: ='📈 PORTEFEUILLE'!L15 | K5: =IFERROR('📈 PORTEFEUILLE'!G15*'📈 PORTEFEUILLE'!H15,0) | L5: ='📈 PORTEFEUILLE'!N15 | M5: ='📈 PORTEFEUILLE'!O15 | N5: ='📈 PORTEFEUILLE'!P15 | O5: 0.0092 | P5: 126.38371 | Q5: 10.531976 | R5: ='📈 PORTEFEUILLE'!Q15
A6: ='📈 PORTEFEUILLE'!B29 | B6: ='📈 PORTEFEUILLE'!C29 | C6: ='📈 PORTEFEUILLE'!D29 | D6: ='📈 PORTEFEUILLE'!E29 | E6: ='📈 PORTEFEUILLE'!F29 | F6: ='📈 PORTEFEUILLE'!G29 | G6: ='📈 PORTEFEUILLE'!I29 | H6: ='📈 PORTEFEUILLE'!K29 | I6: ='📈 PORTEFEUILLE'!I29 | J6: ='📈 PORTEFEUILLE'!L29 | K6: =IFERROR('📈 PORTEFEUILLE'!G29*'📈 PORTEFEUILLE'!H29,0) | L6: ='📈 PORTEFEUILLE'!N29 | M6: ='📈 PORTEFEUILLE'!O29 | N6: ='📈 PORTEFEUILLE'!P29 | O6: 0.048 | P6: 544.17456 | Q6: 45.34788 | R6: ='📈 PORTEFEUILLE'!Q29
A7: ='📈 PORTEFEUILLE'!B19 | B7: ='📈 PORTEFEUILLE'!C19 | C7: ='📈 PORTEFEUILLE'!D19 | D7: ='📈 PORTEFEUILLE'!E19 | E7: ='📈 PORTEFEUILLE'!F19 | F7: ='📈 PORTEFEUILLE'!G19 | G7: ='📈 PORTEFEUILLE'!I19 | H7: ='📈 PORTEFEUILLE'!K19 | I7: ='📈 PORTEFEUILLE'!I19 | J7: ='📈 PORTEFEUILLE'!L19 | K7: =IFERROR('📈 PORTEFEUILLE'!G19*'📈 PORTEFEUILLE'!H19,0) | L7: ='📈 PORTEFEUILLE'!N19 | M7: ='📈 PORTEFEUILLE'!O19 | N7: ='📈 PORTEFEUILLE'!P19 | O7: 0.007 | P7: 72.596073 | Q7: 6.0496728 | R7: ='📈 PORTEFEUILLE'!Q19
A8: ='📈 PORTEFEUILLE'!B17 | B8: ='📈 PORTEFEUILLE'!C17 | C8: ='📈 PORTEFEUILLE'!D17 | D8: ='📈 PORTEFEUILLE'!E17 | E8: ='📈 PORTEFEUILLE'!F17 | F8: ='📈 PORTEFEUILLE'!G17 | G8: ='📈 PORTEFEUILLE'!I17 | H8: ='📈 PORTEFEUILLE'!K17 | I8: ='📈 PORTEFEUILLE'!I17 | J8: ='📈 PORTEFEUILLE'!L17 | K8: =IFERROR('📈 PORTEFEUILLE'!G17*'📈 PORTEFEUILLE'!H17,0) | L8: ='📈 PORTEFEUILLE'!N17 | M8: ='📈 PORTEFEUILLE'!O17 | N8: ='📈 PORTEFEUILLE'!P17 | O8: 0.012 | P8: 91.446739 | Q8: 7.6205616 | R8: ='📈 PORTEFEUILLE'!Q17
A9: ='📈 PORTEFEUILLE'!B22 | B9: ='📈 PORTEFEUILLE'!C22 | C9: ='📈 PORTEFEUILLE'!D22 | D9: ='📈 PORTEFEUILLE'!E22 | E9: ='📈 PORTEFEUILLE'!F22 | F9: ='📈 PORTEFEUILLE'!G22 | G9: ='📈 PORTEFEUILLE'!I22 | H9: ='📈 PORTEFEUILLE'!K22 | I9: ='📈 PORTEFEUILLE'!I22 | J9: ='📈 PORTEFEUILLE'!L22 | K9: =IFERROR('📈 PORTEFEUILLE'!G22*'📈 PORTEFEUILLE'!H22,0) | L9: ='📈 PORTEFEUILLE'!N22 | M9: ='📈 PORTEFEUILLE'!O22 | N9: ='📈 PORTEFEUILLE'!P22 | O9: 0.003 | P9: 8.3536708 | Q9: 0.69613923 | R9: ='📈 PORTEFEUILLE'!Q22
A10: ='📈 PORTEFEUILLE'!B62 | B10: ='📈 PORTEFEUILLE'!C62 | C10: ='📈 PORTEFEUILLE'!D62 | D10: ='📈 PORTEFEUILLE'!E62 | E10: ='📈 PORTEFEUILLE'!F62 | F10: ='📈 PORTEFEUILLE'!G62 | G10: ='📈 PORTEFEUILLE'!I62 | H10: ='📈 PORTEFEUILLE'!K62 | I10: ='📈 PORTEFEUILLE'!I62 | J10: ='📈 PORTEFEUILLE'!L62 | K10: =IFERROR('📈 PORTEFEUILLE'!G62*'📈 PORTEFEUILLE'!H62,0) | L10: ='📈 PORTEFEUILLE'!N62 | M10: ='📈 PORTEFEUILLE'!O62 | N10: ='📈 PORTEFEUILLE'!P62 | O10: 0.035 | P10: 94.436704 | Q10: 7.8697254 | R10: ='📈 PORTEFEUILLE'!Q62
A11: ='📈 PORTEFEUILLE'!B47 | B11: ='📈 PORTEFEUILLE'!C47 | C11: ='📈 PORTEFEUILLE'!D47 | D11: ='📈 PORTEFEUILLE'!E47 | E11: ='📈 PORTEFEUILLE'!F47 | F11: ='📈 PORTEFEUILLE'!G47 | G11: ='📈 PORTEFEUILLE'!I47 | H11: ='📈 PORTEFEUILLE'!K47 | I11: ='📈 PORTEFEUILLE'!I47 | J11: ='📈 PORTEFEUILLE'!L47 | K11: =IFERROR('📈 PORTEFEUILLE'!G47*'📈 PORTEFEUILLE'!H47,0) | L11: ='📈 PORTEFEUILLE'!N47 | M11: ='📈 PORTEFEUILLE'!O47 | N11: ='📈 PORTEFEUILLE'!P47 | O11: 0.0092 | P11: 24.073088 | Q11: 2.0060907 | R11: ='📈 PORTEFEUILLE'!Q47
A12: ='📈 PORTEFEUILLE'!B16 | B12: ='📈 PORTEFEUILLE'!C16 | C12: ='📈 PORTEFEUILLE'!D16 | D12: ='📈 PORTEFEUILLE'!E16 | E12: ='📈 PORTEFEUILLE'!F16 | F12: ='📈 PORTEFEUILLE'!G16 | G12: ='📈 PORTEFEUILLE'!I16 | H12: ='📈 PORTEFEUILLE'!K16 | I12: ='📈 PORTEFEUILLE'!I16 | J12: ='📈 PORTEFEUILLE'!L16 | K12: =IFERROR('📈 PORTEFEUILLE'!G16*'📈 PORTEFEUILLE'!H16,0) | L12: ='📈 PORTEFEUILLE'!N16 | M12: ='📈 PORTEFEUILLE'!O16 | N12: ='📈 PORTEFEUILLE'!P16 | O12: 0.005 | P12: 12.462868 | Q12: 1.0385724 | R12: ='📈 PORTEFEUILLE'!Q16
A13: ='📈 PORTEFEUILLE'!B30 | B13: ='📈 PORTEFEUILLE'!C30 | C13: ='📈 PORTEFEUILLE'!D30 | D13: ='📈 PORTEFEUILLE'!E30 | E13: ='📈 PORTEFEUILLE'!F30 | F13: ='📈 PORTEFEUILLE'!G30 | G13: ='📈 PORTEFEUILLE'!I30 | H13: ='📈 PORTEFEUILLE'!K30 | I13: ='📈 PORTEFEUILLE'!I30 | J13: ='📈 PORTEFEUILLE'!L30 | K13: =IFERROR('📈 PORTEFEUILLE'!G30*'📈 PORTEFEUILLE'!H30,0) | L13: ='📈 PORTEFEUILLE'!N30 | M13: ='📈 PORTEFEUILLE'!O30 | N13: ='📈 PORTEFEUILLE'!P30 | O13: 0.024 | P13: 52.40088 | Q13: 4.36674 | R13: ='📈 PORTEFEUILLE'!Q30
A14: ='📈 PORTEFEUILLE'!B18 | B14: ='📈 PORTEFEUILLE'!C18 | C14: ='📈 PORTEFEUILLE'!D18 | D14: ='📈 PORTEFEUILLE'!E18 | E14: ='📈 PORTEFEUILLE'!F18 | F14: ='📈 PORTEFEUILLE'!G18 | G14: ='📈 PORTEFEUILLE'!I18 | H14: ='📈 PORTEFEUILLE'!K18 | I14: ='📈 PORTEFEUILLE'!I18 | J14: ='📈 PORTEFEUILLE'!L18 | K14: =IFERROR('📈 PORTEFEUILLE'!G18*'📈 PORTEFEUILLE'!H18,0) | L14: ='📈 PORTEFEUILLE'!N18 | M14: ='📈 PORTEFEUILLE'!O18 | N14: ='📈 PORTEFEUILLE'!P18 | O14: 0 | P14: 0 | Q14: 0 | R14: ='📈 PORTEFEUILLE'!Q18
A15: ='📈 PORTEFEUILLE'!B48 | B15: ='📈 PORTEFEUILLE'!C48 | C15: ='📈 PORTEFEUILLE'!D48 | D15: ='📈 PORTEFEUILLE'!E48 | E15: ='📈 PORTEFEUILLE'!F48 | F15: ='📈 PORTEFEUILLE'!G48 | G15: ='📈 PORTEFEUILLE'!I48 | H15: ='📈 PORTEFEUILLE'!K48 | I15: ='📈 PORTEFEUILLE'!I48 | J15: ='📈 PORTEFEUILLE'!L48 | K15: =IFERROR('📈 PORTEFEUILLE'!G48*'📈 PORTEFEUILLE'!H48,0) | L15: ='📈 PORTEFEUILLE'!N48 | M15: ='📈 PORTEFEUILLE'!O48 | N15: ='📈 PORTEFEUILLE'!P48 | O15: 0 | P15: 0 | Q15: 0 | R15: ='📈 PORTEFEUILLE'!Q48
A16: ='📈 PORTEFEUILLE'!B51 | B16: ='📈 PORTEFEUILLE'!C51 | C16: ='📈 PORTEFEUILLE'!D51 | D16: ='📈 PORTEFEUILLE'!E51 | E16: ='📈 PORTEFEUILLE'!F51 | F16: ='📈 PORTEFEUILLE'!G51 | G16: ='📈 PORTEFEUILLE'!I51 | H16: ='📈 PORTEFEUILLE'!K51 | I16: ='📈 PORTEFEUILLE'!I51 | J16: ='📈 PORTEFEUILLE'!L51 | K16: =IFERROR('📈 PORTEFEUILLE'!G51*'📈 PORTEFEUILLE'!H51,0) | L16: ='📈 PORTEFEUILLE'!N51 | M16: ='📈 PORTEFEUILLE'!O51 | N16: ='📈 PORTEFEUILLE'!P51 | O16: 0.048 | P16: 93.8232 | Q16: 7.8186 | R16: ='📈 PORTEFEUILLE'!Q51
A17: ='📈 PORTEFEUILLE'!B37 | B17: ='📈 PORTEFEUILLE'!C37 | C17: ='📈 PORTEFEUILLE'!D37 | D17: ='📈 PORTEFEUILLE'!E37 | E17: ='📈 PORTEFEUILLE'!F37 | F17: ='📈 PORTEFEUILLE'!G37 | G17: ='📈 PORTEFEUILLE'!I37 | H17: ='📈 PORTEFEUILLE'!K37 | I17: ='📈 PORTEFEUILLE'!I37 | J17: ='📈 PORTEFEUILLE'!L37 | K17: =IFERROR('📈 PORTEFEUILLE'!G37*'📈 PORTEFEUILLE'!H37,0) | L17: ='📈 PORTEFEUILLE'!N37 | M17: ='📈 PORTEFEUILLE'!O37 | N17: ='📈 PORTEFEUILLE'!P37 | O17: 0.055 | P17: 100.1385 | Q17: 8.344875 | R17: ='📈 PORTEFEUILLE'!Q37
A18: ='📈 PORTEFEUILLE'!B49 | B18: ='📈 PORTEFEUILLE'!C49 | C18: ='📈 PORTEFEUILLE'!D49 | D18: ='📈 PORTEFEUILLE'!E49 | E18: ='📈 PORTEFEUILLE'!F49 | F18: ='📈 PORTEFEUILLE'!G49 | G18: ='📈 PORTEFEUILLE'!I49 | H18: ='📈 PORTEFEUILLE'!K49 | I18: ='📈 PORTEFEUILLE'!I49 | J18: ='📈 PORTEFEUILLE'!L49 | K18: =IFERROR('📈 PORTEFEUILLE'!G49*'📈 PORTEFEUILLE'!H49,0) | L18: ='📈 PORTEFEUILLE'!N49 | M18: ='📈 PORTEFEUILLE'!O49 | N18: ='📈 PORTEFEUILLE'!P49 | O18: 0.006 | P18: 10.750288 | Q18: 0.89585737 | R18: ='📈 PORTEFEUILLE'!Q49
A19: ='📈 PORTEFEUILLE'!B54 | B19: ='📈 PORTEFEUILLE'!C54 | C19: ='📈 PORTEFEUILLE'!D54 | D19: ='📈 PORTEFEUILLE'!E54 | E19: ='📈 PORTEFEUILLE'!F54 | F19: ='📈 PORTEFEUILLE'!G54 | G19: ='📈 PORTEFEUILLE'!I54 | H19: ='📈 PORTEFEUILLE'!K54 | I19: ='📈 PORTEFEUILLE'!I54 | J19: ='📈 PORTEFEUILLE'!L54 | K19: =IFERROR('📈 PORTEFEUILLE'!G54*'📈 PORTEFEUILLE'!H54,0) | L19: ='📈 PORTEFEUILLE'!N54 | M19: ='📈 PORTEFEUILLE'!O54 | N19: ='📈 PORTEFEUILLE'!P54 | O19: 0.072 | P19: 121.338 | Q19: 10.1115 | R19: ='📈 PORTEFEUILLE'!Q54
A20: ='📈 PORTEFEUILLE'!B55 | B20: ='📈 PORTEFEUILLE'!C55 | C20: ='📈 PORTEFEUILLE'!D55 | D20: ='📈 PORTEFEUILLE'!E55 | E20: ='📈 PORTEFEUILLE'!F55 | F20: ='📈 PORTEFEUILLE'!G55 | G20: ='📈 PORTEFEUILLE'!I55 | H20: ='📈 PORTEFEUILLE'!K55 | I20: ='📈 PORTEFEUILLE'!I55 | J20: ='📈 PORTEFEUILLE'!L55 | K20: =IFERROR('📈 PORTEFEUILLE'!G55*'📈 PORTEFEUILLE'!H55,0) | L20: ='📈 PORTEFEUILLE'!N55 | M20: ='📈 PORTEFEUILLE'!O55 | N20: ='📈 PORTEFEUILLE'!P55 | O20: 0.056 | P20: 85.5232 | Q20: 7.1269333 | R20: ='📈 PORTEFEUILLE'!Q55
A21: ='📈 PORTEFEUILLE'!B38 | B21: ='📈 PORTEFEUILLE'!C38 | C21: ='📈 PORTEFEUILLE'!D38 | D21: ='📈 PORTEFEUILLE'!E38 | E21: ='📈 PORTEFEUILLE'!F38 | F21: ='📈 PORTEFEUILLE'!G38 | G21: ='📈 PORTEFEUILLE'!I38 | H21: ='📈 PORTEFEUILLE'!K38 | I21: ='📈 PORTEFEUILLE'!I38 | J21: ='📈 PORTEFEUILLE'!L38 | K21: =IFERROR('📈 PORTEFEUILLE'!G38*'📈 PORTEFEUILLE'!H38,0) | L21: ='📈 PORTEFEUILLE'!N38 | M21: ='📈 PORTEFEUILLE'!O38 | N21: ='📈 PORTEFEUILLE'!P38 | O21: 0.072 | P21: 109.782 | Q21: 9.1485 | R21: ='📈 PORTEFEUILLE'!Q38
A22: ='📈 PORTEFEUILLE'!B26 | B22: ='📈 PORTEFEUILLE'!C26 | C22: ='📈 PORTEFEUILLE'!D26 | D22: ='📈 PORTEFEUILLE'!E26 | E22: ='📈 PORTEFEUILLE'!F26 | F22: ='📈 PORTEFEUILLE'!G26 | G22: ='📈 PORTEFEUILLE'!I26 | H22: ='📈 PORTEFEUILLE'!K26 | I22: ='📈 PORTEFEUILLE'!I26 | J22: ='📈 PORTEFEUILLE'!L26 | K22: =IFERROR('📈 PORTEFEUILLE'!G26*'📈 PORTEFEUILLE'!H26,0) | L22: ='📈 PORTEFEUILLE'!N26 | M22: ='📈 PORTEFEUILLE'!O26 | N22: ='📈 PORTEFEUILLE'!P26 | O22: 0.006 | P22: 9.010527 | Q22: 0.75087725 | R22: ='📈 PORTEFEUILLE'!Q26
A23: ='📈 PORTEFEUILLE'!B31 | B23: ='📈 PORTEFEUILLE'!C31 | C23: ='📈 PORTEFEUILLE'!D31 | D23: ='📈 PORTEFEUILLE'!E31 | E23: ='📈 PORTEFEUILLE'!F31 | F23: ='📈 PORTEFEUILLE'!G31 | G23: ='📈 PORTEFEUILLE'!I31 | H23: ='📈 PORTEFEUILLE'!K31 | I23: ='📈 PORTEFEUILLE'!I31 | J23: ='📈 PORTEFEUILLE'!L31 | K23: =IFERROR('📈 PORTEFEUILLE'!G31*'📈 PORTEFEUILLE'!H31,0) | L23: ='📈 PORTEFEUILLE'!N31 | M23: ='📈 PORTEFEUILLE'!O31 | N23: ='📈 PORTEFEUILLE'!P31 | O23: 0.03 | P23: 38.7222 | Q23: 3.22685 | R23: ='📈 PORTEFEUILLE'!Q31
A24: ='📈 PORTEFEUILLE'!B39 | B24: ='📈 PORTEFEUILLE'!C39 | C24: ='📈 PORTEFEUILLE'!D39 | D24: ='📈 PORTEFEUILLE'!E39 | E24: ='📈 PORTEFEUILLE'!F39 | F24: ='📈 PORTEFEUILLE'!G39 | G24: ='📈 PORTEFEUILLE'!I39 | H24: ='📈 PORTEFEUILLE'!K39 | I24: ='📈 PORTEFEUILLE'!I39 | J24: ='📈 PORTEFEUILLE'!L39 | K24: =IFERROR('📈 PORTEFEUILLE'!G39*'📈 PORTEFEUILLE'!H39,0) | L24: ='📈 PORTEFEUILLE'!N39 | M24: ='📈 PORTEFEUILLE'!O39 | N24: ='📈 PORTEFEUILLE'!P39 | O24: 0.025 | P24: 27.8355 | Q24: 2.319625 | R24: ='📈 PORTEFEUILLE'!Q39
A25: ='📈 PORTEFEUILLE'!B23 | B25: ='📈 PORTEFEUILLE'!C23 | C25: ='📈 PORTEFEUILLE'!D23 | D25: ='📈 PORTEFEUILLE'!E23 | E25: ='📈 PORTEFEUILLE'!F23 | F25: ='📈 PORTEFEUILLE'!G23 | G25: ='📈 PORTEFEUILLE'!I23 | H25: ='📈 PORTEFEUILLE'!K23 | I25: ='📈 PORTEFEUILLE'!I23 | J25: ='📈 PORTEFEUILLE'!L23 | K25: =IFERROR('📈 PORTEFEUILLE'!G23*'📈 PORTEFEUILLE'!H23,0) | L25: ='📈 PORTEFEUILLE'!N23 | M25: ='📈 PORTEFEUILLE'!O23 | N25: ='📈 PORTEFEUILLE'!P23 | O25: 0.008 | P25: 8.7516451 | Q25: 0.72930375 | R25: ='📈 PORTEFEUILLE'!Q23
A26: ='📈 PORTEFEUILLE'!B25 | B26: ='📈 PORTEFEUILLE'!C25 | C26: ='📈 PORTEFEUILLE'!D25 | D26: ='📈 PORTEFEUILLE'!E25 | E26: ='📈 PORTEFEUILLE'!F25 | F26: ='📈 PORTEFEUILLE'!G25 | G26: ='📈 PORTEFEUILLE'!I25 | H26: ='📈 PORTEFEUILLE'!K25 | I26: ='📈 PORTEFEUILLE'!I25 | J26: ='📈 PORTEFEUILLE'!L25 | K26: =IFERROR('📈 PORTEFEUILLE'!G25*'📈 PORTEFEUILLE'!H25,0) | L26: ='📈 PORTEFEUILLE'!N25 | M26: ='📈 PORTEFEUILLE'!O25 | N26: ='📈 PORTEFEUILLE'!P25 | O26: 0 | P26: 0 | Q26: 0 | R26: ='📈 PORTEFEUILLE'!Q25
A27: ='📈 PORTEFEUILLE'!B27 | B27: ='📈 PORTEFEUILLE'!C27 | C27: ='📈 PORTEFEUILLE'!D27 | D27: ='📈 PORTEFEUILLE'!E27 | E27: ='📈 PORTEFEUILLE'!F27 | F27: ='📈 PORTEFEUILLE'!G27 | G27: ='📈 PORTEFEUILLE'!I27 | H27: ='📈 PORTEFEUILLE'!K27 | I27: ='📈 PORTEFEUILLE'!I27 | J27: ='📈 PORTEFEUILLE'!L27 | K27: =IFERROR('📈 PORTEFEUILLE'!G27*'📈 PORTEFEUILLE'!H27,0) | L27: ='📈 PORTEFEUILLE'!N27 | M27: ='📈 PORTEFEUILLE'!O27 | N27: ='📈 PORTEFEUILLE'!P27 | O27: 0.02 | P27: 20.23 | Q27: 1.6858333 | R27: ='📈 PORTEFEUILLE'!Q27
A28: ='📈 PORTEFEUILLE'!B56 | B28: ='📈 PORTEFEUILLE'!C56 | C28: ='📈 PORTEFEUILLE'!D56 | D28: ='📈 PORTEFEUILLE'!E56 | E28: ='📈 PORTEFEUILLE'!F56 | F28: ='📈 PORTEFEUILLE'!G56 | G28: ='📈 PORTEFEUILLE'!I56 | H28: ='📈 PORTEFEUILLE'!K56 | I28: ='📈 PORTEFEUILLE'!I56 | J28: ='📈 PORTEFEUILLE'!L56 | K28: =IFERROR('📈 PORTEFEUILLE'!G56*'📈 PORTEFEUILLE'!H56,0) | L28: ='📈 PORTEFEUILLE'!N56 | M28: ='📈 PORTEFEUILLE'!O56 | N28: ='📈 PORTEFEUILLE'!P56 | O28: 0.025 | P28: 25.1845 | Q28: 2.0987083 | R28: ='📈 PORTEFEUILLE'!Q56
A29: ='📈 PORTEFEUILLE'!B24 | B29: ='📈 PORTEFEUILLE'!C24 | C29: ='📈 PORTEFEUILLE'!D24 | D29: ='📈 PORTEFEUILLE'!E24 | E29: ='📈 PORTEFEUILLE'!F24 | F29: ='📈 PORTEFEUILLE'!G24 | G29: ='📈 PORTEFEUILLE'!I24 | H29: ='📈 PORTEFEUILLE'!K24 | I29: ='📈 PORTEFEUILLE'!I24 | J29: ='📈 PORTEFEUILLE'!L24 | K29: =IFERROR('📈 PORTEFEUILLE'!G24*'📈 PORTEFEUILLE'!H24,0) | L29: ='📈 PORTEFEUILLE'!N24 | M29: ='📈 PORTEFEUILLE'!O24 | N29: ='📈 PORTEFEUILLE'!P24 | O29: 0.003 | P29: 3.006365 | Q29: 0.25053042 | R29: ='📈 PORTEFEUILLE'!Q24
A30: ='📈 PORTEFEUILLE'!B57 | B30: ='📈 PORTEFEUILLE'!C57 | C30: ='📈 PORTEFEUILLE'!D57 | D30: ='📈 PORTEFEUILLE'!E57 | E30: ='📈 PORTEFEUILLE'!F57 | F30: ='📈 PORTEFEUILLE'!G57 | G30: ='📈 PORTEFEUILLE'!I57 | H30: ='📈 PORTEFEUILLE'!K57 | I30: ='📈 PORTEFEUILLE'!I57 | J30: ='📈 PORTEFEUILLE'!L57 | K30: =IFERROR('📈 PORTEFEUILLE'!G57*'📈 PORTEFEUILLE'!H57,0) | L30: ='📈 PORTEFEUILLE'!N57 | M30: ='📈 PORTEFEUILLE'!O57 | N30: ='📈 PORTEFEUILLE'!P57 | O30: 0.055 | P30: 51.051 | Q30: 4.25425 | R30: ='📈 PORTEFEUILLE'!Q57
A31: ='📈 PORTEFEUILLE'!B20 | B31: ='📈 PORTEFEUILLE'!C20 | C31: ='📈 PORTEFEUILLE'!D20 | D31: ='📈 PORTEFEUILLE'!E20 | E31: ='📈 PORTEFEUILLE'!F20 | F31: ='📈 PORTEFEUILLE'!G20 | G31: ='📈 PORTEFEUILLE'!I20 | H31: ='📈 PORTEFEUILLE'!K20 | I31: ='📈 PORTEFEUILLE'!I20 | J31: ='📈 PORTEFEUILLE'!L20 | K31: =IFERROR('📈 PORTEFEUILLE'!G20*'📈 PORTEFEUILLE'!H20,0) | L31: ='📈 PORTEFEUILLE'!N20 | M31: ='📈 PORTEFEUILLE'!O20 | N31: ='📈 PORTEFEUILLE'!P20 | O31: 0.004 | P31: 3.5335398 | Q31: 0.29446165 | R31: ='📈 PORTEFEUILLE'!Q20
A32: ='📈 PORTEFEUILLE'!B33 | B32: ='📈 PORTEFEUILLE'!C33 | C32: ='📈 PORTEFEUILLE'!D33 | D32: ='📈 PORTEFEUILLE'!E33 | E32: ='📈 PORTEFEUILLE'!F33 | F32: ='📈 PORTEFEUILLE'!G33 | G32: ='📈 PORTEFEUILLE'!I33 | H32: ='📈 PORTEFEUILLE'!K33 | I32: ='📈 PORTEFEUILLE'!I33 | J32: ='📈 PORTEFEUILLE'!L33 | K32: =IFERROR('📈 PORTEFEUILLE'!G33*'📈 PORTEFEUILLE'!H33,0) | L32: ='📈 PORTEFEUILLE'!N33 | M32: ='📈 PORTEFEUILLE'!O33 | N32: ='📈 PORTEFEUILLE'!P33 | O32: 0.004 | P32: 3.0591369 | Q32: 0.25492808 | R32: ='📈 PORTEFEUILLE'!Q33
A33: ='📈 PORTEFEUILLE'!B21 | B33: ='📈 PORTEFEUILLE'!C21 | C33: ='📈 PORTEFEUILLE'!D21 | D33: ='📈 PORTEFEUILLE'!E21 | E33: ='📈 PORTEFEUILLE'!F21 | F33: ='📈 PORTEFEUILLE'!G21 | G33: ='📈 PORTEFEUILLE'!I21 | H33: ='📈 PORTEFEUILLE'!K21 | I33: ='📈 PORTEFEUILLE'!I21 | J33: ='📈 PORTEFEUILLE'!L21 | K33: =IFERROR('📈 PORTEFEUILLE'!G21*'📈 PORTEFEUILLE'!H21,0) | L33: ='📈 PORTEFEUILLE'!N21 | M33: ='📈 PORTEFEUILLE'!O21 | N33: ='📈 PORTEFEUILLE'!P21 | O33: 0.065 | P33: 42.6231 | Q33: 3.551925 | R33: ='📈 PORTEFEUILLE'!Q21
A34: ='📈 PORTEFEUILLE'!B50 | B34: ='📈 PORTEFEUILLE'!C50 | C34: ='📈 PORTEFEUILLE'!D50 | D34: ='📈 PORTEFEUILLE'!E50 | E34: ='📈 PORTEFEUILLE'!F50 | F34: ='📈 PORTEFEUILLE'!G50 | G34: ='📈 PORTEFEUILLE'!I50 | H34: ='📈 PORTEFEUILLE'!K50 | I34: ='📈 PORTEFEUILLE'!I50 | J34: ='📈 PORTEFEUILLE'!L50 | K34: =IFERROR('📈 PORTEFEUILLE'!G50*'📈 PORTEFEUILLE'!H50,0) | L34: ='📈 PORTEFEUILLE'!N50 | M34: ='📈 PORTEFEUILLE'!O50 | N34: ='📈 PORTEFEUILLE'!P50 | O34: 0.02 | P34: 12.138 | Q34: 1.0115 | R34: ='📈 PORTEFEUILLE'!Q50
A35: ='📈 PORTEFEUILLE'!B52 | B35: ='📈 PORTEFEUILLE'!C52 | C35: ='📈 PORTEFEUILLE'!D52 | D35: ='📈 PORTEFEUILLE'!E52 | E35: ='📈 PORTEFEUILLE'!F52 | F35: ='📈 PORTEFEUILLE'!G52 | G35: ='📈 PORTEFEUILLE'!I52 | H35: ='📈 PORTEFEUILLE'!K52 | I35: ='📈 PORTEFEUILLE'!I52 | J35: ='📈 PORTEFEUILLE'!L52 | K35: =IFERROR('📈 PORTEFEUILLE'!G52*'📈 PORTEFEUILLE'!H52,0) | L35: ='📈 PORTEFEUILLE'!N52 | M35: ='📈 PORTEFEUILLE'!O52 | N35: ='📈 PORTEFEUILLE'!P52 | O35: 0.03 | P35: 17.601 | Q35: 1.46675 | R35: ='📈 PORTEFEUILLE'!Q52
A36: ='📈 PORTEFEUILLE'!B28 | B36: ='📈 PORTEFEUILLE'!C28 | C36: ='📈 PORTEFEUILLE'!D28 | D36: ='📈 PORTEFEUILLE'!E28 | E36: ='📈 PORTEFEUILLE'!F28 | F36: ='📈 PORTEFEUILLE'!G28 | G36: ='📈 PORTEFEUILLE'!I28 | H36: ='📈 PORTEFEUILLE'!K28 | I36: ='📈 PORTEFEUILLE'!I28 | J36: ='📈 PORTEFEUILLE'!L28 | K36: =IFERROR('📈 PORTEFEUILLE'!G28*'📈 PORTEFEUILLE'!H28,0) | L36: ='📈 PORTEFEUILLE'!N28 | M36: ='📈 PORTEFEUILLE'!O28 | N36: ='📈 PORTEFEUILLE'!P28 | O36: 0.009 | P36: 5.2158413 | Q36: 0.43465344 | R36: ='📈 PORTEFEUILLE'!Q28
A37: ='📈 PORTEFEUILLE'!B32 | B37: ='📈 PORTEFEUILLE'!C32 | C37: ='📈 PORTEFEUILLE'!D32 | D37: ='📈 PORTEFEUILLE'!E32 | E37: ='📈 PORTEFEUILLE'!F32 | F37: ='📈 PORTEFEUILLE'!G32 | G37: ='📈 PORTEFEUILLE'!I32 | H37: ='📈 PORTEFEUILLE'!K32 | I37: ='📈 PORTEFEUILLE'!I32 | J37: ='📈 PORTEFEUILLE'!L32 | K37: =IFERROR('📈 PORTEFEUILLE'!G32*'📈 PORTEFEUILLE'!H32,0) | L37: ='📈 PORTEFEUILLE'!N32 | M37: ='📈 PORTEFEUILLE'!O32 | N37: ='📈 PORTEFEUILLE'!P32 | O37: 0.085 | P37: 49.0688 | Q37: 4.0890667 | R37: ='📈 PORTEFEUILLE'!Q32
A38: ='📈 PORTEFEUILLE'!B40 | B38: ='📈 PORTEFEUILLE'!C40 | C38: ='📈 PORTEFEUILLE'!D40 | D38: ='📈 PORTEFEUILLE'!E40 | E38: ='📈 PORTEFEUILLE'!F40 | F38: ='📈 PORTEFEUILLE'!G40 | G38: ='📈 PORTEFEUILLE'!I40 | H38: ='📈 PORTEFEUILLE'!K40 | I38: ='📈 PORTEFEUILLE'!I40 | J38: ='📈 PORTEFEUILLE'!L40 | K38: =IFERROR('📈 PORTEFEUILLE'!G40*'📈 PORTEFEUILLE'!H40,0) | L38: ='📈 PORTEFEUILLE'!N40 | M38: ='📈 PORTEFEUILLE'!O40 | N38: ='📈 PORTEFEUILLE'!P40 | O38: 0.05 | P38: 21.4225 | Q38: 1.7852083 | R38: ='📈 PORTEFEUILLE'!Q40
A39: ='📈 PORTEFEUILLE'!B41 | B39: ='📈 PORTEFEUILLE'!C41 | C39: ='📈 PORTEFEUILLE'!D41 | D39: ='📈 PORTEFEUILLE'!E41 | E39: ='📈 PORTEFEUILLE'!F41 | F39: ='📈 PORTEFEUILLE'!G41 | G39: ='📈 PORTEFEUILLE'!I41 | H39: ='📈 PORTEFEUILLE'!K41 | I39: ='📈 PORTEFEUILLE'!I41 | J39: ='📈 PORTEFEUILLE'!L41 | K39: =IFERROR('📈 PORTEFEUILLE'!G41*'📈 PORTEFEUILLE'!H41,0) | L39: ='📈 PORTEFEUILLE'!N41 | M39: ='📈 PORTEFEUILLE'!O41 | N39: ='📈 PORTEFEUILLE'!P41 | O39: 0.044 | P39: 16.14624 | Q39: 1.34552 | R39: ='📈 PORTEFEUILLE'!Q41
A40: ='📈 PORTEFEUILLE'!B34 | B40: ='📈 PORTEFEUILLE'!C34 | C40: ='📈 PORTEFEUILLE'!D34 | D40: ='📈 PORTEFEUILLE'!E34 | E40: ='📈 PORTEFEUILLE'!F34 | F40: ='📈 PORTEFEUILLE'!G34 | G40: ='📈 PORTEFEUILLE'!I34 | H40: ='📈 PORTEFEUILLE'!K34 | I40: ='📈 PORTEFEUILLE'!I34 | J40: ='📈 PORTEFEUILLE'!L34 | K40: =IFERROR('📈 PORTEFEUILLE'!G34*'📈 PORTEFEUILLE'!H34,0) | L40: ='📈 PORTEFEUILLE'!N34 | M40: ='📈 PORTEFEUILLE'!O34 | N40: ='📈 PORTEFEUILLE'!P34 | O40: 0.002 | P40: 0.71424 | Q40: 0.05952 | R40: ='📈 PORTEFEUILLE'!Q34
...

Sheet 🏠 DASHBOARD
B1: 🏠 TABLEAU DE BORD · PORTEFEUILLE FI · MAXIMIZE — PAS DE CIBLE, TOUJOURS PLUS
B2: v49-S19 · 12 mars 2026 · Partenaire FI permanent : Claude · Plan $5,000/mois structuré
B4: ① STATUT SESSION · Cocher avant de commencer
B5: VÉRIFICATION | C5: VALEUR / STATUT | E5: CONTEXTE MARCHÉ | G5: INTENTION SESSION
B6: 📎 Wallet uploadé? | C6: ⬜ Confirmer | E6: =IFERROR("S&P "&TEXT(CONFIG!G36,"#,##0")&" ("&TEXT(CONFIG!B49,"+0.0%")&")","S&P: N/A") | G6: ⬜ Dire à Claude
B7: 📋 Questrade dump? | C7: ⬜ Confirmer | E7: =IFERROR("TSX "&TEXT(CONFIG!G37,"#,##0")&" ("&TEXT(CONFIG!B50,"+0.0%")&")","TSX: N/A") | G7: BdC 18 mars · Fed 18-19 mars
B8: 💱 USD/CAD | C8: =CONFIG!B3 | E8: =IFERROR("USD/CAD "&TEXT(CONFIG!B3,"0.0000"),"N/A") | G8: =IFERROR(TEXT(NOW(),"dd mmm yyyy HH:MM")&" HNE","--")
B9: 💰 Cash TFSA / FHSA | C9: =CONFIG!B37 | E9: =CONFIG!B38 | G9: VIX: saisir ⬜
B11: ② PORTFOLIO LIVE · Valeurs en temps réel depuis 📈 PORTEFEUILLE
B12: COMPTE | C12: VALEUR ACTUELLE | D12: DÉPOSÉ | E12: P&L $ | F12: P&L % | G12: ROOM DISPO | H12: NOTE / RÔLE
B13: TFSA 📈 | C13: ='📈 PORTEFEUILLE'!L44 | D13: ='📈 PORTEFEUILLE'!M44 | E13: ='📈 PORTEFEUILLE'!N44 | F13: ='📈 PORTEFEUILLE'!O44 | G13: =CONFIG!B6 | H13: Croissance LT · Retraite · Intouchable
B14: FHSA 🏠 | C14: ='📈 PORTEFEUILLE'!L59 | D14: ='📈 PORTEFEUILLE'!M59 | E14: ='📈 PORTEFEUILLE'!N59 | F14: ='📈 PORTEFEUILLE'!O59 | G14: =CONFIG!B7 | H14: Maison 2030+ · Double exonération fiscale
B15: REER ❄️🔥 | C15: ='📈 PORTEFEUILLE'!L68 | D15: ='📈 PORTEFEUILLE'!M68 | E15: ='📈 PORTEFEUILLE'!N68 | F15: ='📈 PORTEFEUILLE'!O68 | G15: =CONFIG!B8 | H15: RAP $60K · Snowball ARC $1,060/mois
B16: ▼ TOTAL PORTFOLIO | C16: ='📈 PORTEFEUILLE'!L70 | D16: ='📈 PORTEFEUILLE'!M70 | E16: ='📈 PORTEFEUILLE'!N70 | F16: ='📈 PORTEFEUILLE'!O70 | G16: SNOWBALL: $1,590/mois | H16: Dividendes est. ~$3,200/an
B18: ③ ACTIONS URGENTES · Statut auto
B19: # | C19: ACTION | F19: STATUT | G19: IMPACT | H19: DÉLAI / NOTE
B20: 🔴 1 | C20: Ouvrir EQ Bank — Fonds urgence $15,000 | F20: =IF(CONFIG!B25>=15000,"✅ FAIT",IF(CONFIG!B25>0,"🟡 EN COURS","🔴 À FAIRE")) | G20: Risque ×0 | H20: CE MOIS · Risque opérationnel #1
B21: 🔴 2 | C21: Vendre ZRE.TO + XIC.TO + VDU.TO → T1 (~$1,878) | F21: =IF(SUMIF('📈 PORTEFEUILLE'!B14:B64,"ZRE.TO",'📈 PORTEFEUILLE'!G14:G64)=0,"✅ FAIT","🔴 POST-BdC 18 mars") | G21: ~+$80/an | H21: Post-BdC 18 mars · T4→T1
B22: 🟡 3 | C22: Vérifier Mon Dossier ARC — Revenu net 2025 | F22: 🟡 PLANIFIER | G22: $1,500 crédit | H22: Avant déc 2026 · NON ÉLIG. 2026 ($140K > $129,590)
B23: ✅ 4 | C23: PLZ.UN 961u vendus @ $4.26 → AVGO+GEV+SMH | F23: ✅ EXÉCUTÉ 11 mars | G23: +$4,094 CAD | H23: T4→T1 réalisé
B24: ✅ 5 | C24: SCHD $2,000 REER — 64.3053u @ $30.85 USD | F24: ✅ EXÉCUTÉ 12 mars | G24: +$1,060/mois ARC | H24: Snowball fiscal activé
B26: ④ CHECKLIST DÉCISIONS · OUI/NON avant tout achat
B27: QUESTION | F27: STATUT AUTO | H27: CONTEXTE
B28: 💰 EQ Bank $15K ouvert ? | F28: =IF(CONFIG!B25>=15000,"✅ OUI","🔴 NON — Ouvrir cette semaine") | H28: 7 mois dépenses · sécurité de base
B29: 📊 Expo USD dans les seuils ? | F29: =CONFIG!B47 | H29: Seuil max 65% · auto
B30: 🤖 Expo IA dans les seuils ? | F30: =IF(CONFIG!B31>0.45,"🔴 DÉPASSE 45% — Pause T1 IA","✅ OK — Sous 45%") | H30: Seuil max 45% · auto
B31: 📅 Earnings calendrier vérifié ? | F31: ⬜ Confirmer avant achat T1/T2 | H31: AVGO ~5 déc · GEV ~22 avr · SMH N/A ETF
B32: 🏠 Trade post-BdC 18 mars planifié ? | F32: =IF(DATEVALUE("2026-03-18")>TODAY(),"⏳ BdC dans "&(DATEVALUE("2026-03-18")-TODAY())&" jours","✅ BdC passé") | H32: ZRE.TO + XIC.TO + VDU.TO → T1
B33: 💡 Remboursement ARC prévu ? | F33: =IF(CONFIG!B34>0,"📅 REER "&TEXT(CONFIG!B34,"$#,##0")&" → Remb. ARC ~"&TEXT(CONFIG!B34*CONFIG!B11,"$#,##0"),"⬜ Aucune cotisation")) | H33: À réinvestir dès réception avril 2027
B35: ⑤ OBJECTIF MAISON 2030+ · FHSA $40K + RAP REER $60K = $100K · Achat solo
B36: SOURCE | C36: AUJOURD'HUI | D36: OBJECTIF | E36: MANQUANT | F36: PROGRESSION | G36: STATUT
B37: FHSA | C37: ='📈 PORTEFEUILLE'!L59 | D37: =CONFIG!B14 | E37: =D37-C37 | F37: =IFERROR(C37/D37,0) | G37: =IF(C37/D37>=1,"✅ ATTEINT",IF(C37/D37>=0.8,"🟡 80%+","⏳ En route"))
B38: REER (RAP) | C38: ='📈 PORTEFEUILLE'!L68 | D38: =CONFIG!B15 | E38: =D38-C38 | F38: =IFERROR(C38/D38,0) | G38: =IF(C38/D38>=1,"✅ ATTEINT",IF(C38/D38>=0.8,"🟡 80%+","⏳ En route"))
B39: ▼ TOTAL MAISON | C39: ='📈 PORTEFEUILLE'!L59+'📈 PORTEFEUILLE'!L68 | D39: =CONFIG!B16 | E39: =D39-C39 | F39: =IFERROR(C39/D39,0) | G39: =IF(C39/D39>=1,"✅ ATTEINT",IF(C39/D39>=0.8,"🟡 80%+","⏳ En route"))
B41: ⑥ PROJECTION FI · $2.1M = plancher · pas de plafond · maximiser toujours
B42: SCÉNARIO | C42: @40 ans | D42: @45 ans | E42: @50 ans | F42: @55 ans | G42: @60 ans | H42: NOTE
B43: 6% / an (conservateur) | C43: =IFERROR(CONFIG!B19*(1.06^(40-34))+5000*12*((1.06^(40-34)-1)/0.06),0) | D43: $1,063,923 | E43: $1,761,995 | F43: $2,696,172 | G43: $3,946,312 | H43: ⚠️ FI @50 limit
B44: 8% / an (réaliste) | C44: =IFERROR(CONFIG!B19*(1.08^(40-34))+5000*12*((1.08^(40-34)-1)/0.08),0) | D44: $1,202,162 | E44: $2,118,367 | F44: $3,464,572 | G44: $5,442,589 | H44: ✅ FI @48 (>$2.1M)
B45: 10% / an (optimiste) | C45: =IFERROR(CONFIG!B19*(1.1^(40-34))+5000*12*((1.1^(40-34)-1)/0.1),0) | D45: $1,360,802 | E45: $2,557,891 | F45: $4,485,814 | G45: $7,590,755 | H45: 🚀 FI @46
B47: ⑦ SNOWBALL FISCAL · Chaque dollar REER coûte $0.47 net (52.98% récupéré)
...

Sheet 💵 BUDGET RÉEL
A1: 💵 BUDGET RÉEL · Portrait financier confirmé · Mars 2026 · v56-S33
A2: Données confirmées session S16 · Cellules en jaune = modifier si changement · Formules = auto
A4: 💰 REVENUS NETS MENSUELS
A5: POSTE | B5: MONTANT CAD | C5: TYPE | D5: NOTE
A6: Paie nette base (aux 2 semaines) | B6: 3000 | C6: Aux 2 sem. | D6: $3,000/paie × 26 ÷ 12 = $6,500/mois · Augmentation annuelle prévue
A7: Prime Nunavik (isolement + zone) | B7: 1450 | C7: Mensuel | D7: Confirmé S16 · Vérifier si change
A8: TOTAL REVENU NET /MOIS | B8: =(B6*26/12)+B7 | C8: AUTO · $3,000×26÷12 + $1,450 = $7,950/mois · Corrigé S18 | D8: ← Revenu mensuel disponible réel confirmé
A10: 💸 DÉPENSES MENSUELLES CONFIRMÉES
A11: POSTE | B11: MONTANT CAD | C11: TYPE | D11: NOTE
A12: Logement | B12: 0 | C12: Gratuit ✅ | D12: 100% payé par employeur Nunavik · Confirmé
A13: Internet | B13: 0 | C13: Gratuit ✅ | D13: Inclus logement employeur · Confirmé
A14: Épicerie / nourriture | B14: 400 | C14: Mensuel | D14: ~$400/mois confirmé S16 · Par rotation aux 2 semaines
A15: Téléphone cellulaire | B15: 110 | C15: Mensuel | D15: $110/mois confirmé
A16: Voiture — paiement/financement | B16: 275 | C16: Mensuel | D16: Milieu $200-350 · À confirmer exactement
A17: Voiture — assurance auto | B17: 100 | C17: Mensuel | D17: Milieu $80-120 · À confirmer exactement
A18: Moto — assurance | B18: 80 | C18: Mensuel/Sais. | D18: Milieu $60-100 · Saisonnière · Peut varier
A19: Essence | B19: 50 | C19: Mensuel | D19: Faible — déplacements limités Nunavik
A20: Abonnements (streaming, etc.) | B20: 25 | C20: Mensuel | D20: Netflix, Spotify, etc. · Milieu $0-50
A21: Loisirs / sorties / restaurants | B21: 50 | C21: Mensuel | D21: Très bas · Nunavik · Milieu $0-100
A22: Voyages / vacances (÷12) | B22: 42 | C22: Mensuel | D22: $500/an ÷ 12 · Budget conservateur confirmé
A23: Vêtements / équipement | B23: 50 | C23: Mensuel | D23: Moto, sport, divers · Milieu $0-100
A24: TOTAL DÉPENSES /MOIS | B24: =SUM(B12:B23) | C24: AUTO | D24: ← Somme toutes dépenses confirmées
A26: 📊 BILAN MENSUEL · Disponible vs Plan structuré
A27: POSTE | B27: MONTANT CAD | C27: TYPE | D27: NOTE
A28: Revenu net total | B28: =B8 | C28: AUTO | D28: ← Depuis section revenus
A29: Total dépenses | B29: =B24 | C29: AUTO | D29: ← Depuis section dépenses
A30: DISPONIBLE RÉEL /MOIS | B30: =B28-B29 | C30: AUTO | D30: ← Ce qui reste vraiment · Confirmé ~$6,768/mois
A32: ─── PLAN STRUCTURÉ $5,000/MOIS ───
A33: → REER (SCHD) | B33: 2000 | C33: Mensuel 🔴 | D33: Priorité #1 · Snowball fiscal $1,060/mois ARC · 52.98%
A34: → FHSA (VFV.TO) | B34: 1000 | C34: Mensuel 🔴 | D34: Priorité #2 · Maison 2030 + déduction fiscale
A35: → TFSA (AVGO fractionnel) | B35: 500 | C35: Mensuel 🔴 | D35: Priorité #3 · Croissance T1 long terme
A36: → EQ Bank HISA | B36: 1500 | C36: Mensuel 🆕 | D36: Priorité #4 · Fonds urgence · $15K en 10 mois
A37: TOTAL STRUCTURÉ | B37: =SUM(B33:B36) | C37: AUTO | D37: ← Doit égaler $5,000
A39: SURPLUS LIBRE (non structuré) | B39: =B30-B37 | C39: AUTO | D39: ← Argent libre · vie / loisirs / imprévus · ~$1,768
A40: Taux épargne structuré | B40: =B37/B28 | C40: AUTO | D40: ← % revenu net investi/épargné · Objectif >60%
A46: 🏦 EQ BANK — TRACKER FONDS URGENCE
A47: POSTE | B47: MONTANT CAD | C47: TYPE | D47: NOTE
A48: Contribution mensuelle EQ Bank | B48: 1500 | C48: Mensuel | D48: ← Modifier si changement de plan
A49: Objectif fonds urgence | B49: 15000 | C49: Cible | D49: 7 mois × $1,182 dépenses = $8,274 min · $15K cible confortable
A50: Mois pour atteindre $15K | B50: =B49/B48 | C50: AUTO | D50: ← Au rythme actuel depuis $0
...

Sheet 📊 ANALYSE PRO
A1: ="📊 ANALYSE PROFESSIONNELLE · "&TEXT(TODAY(),"DD MMMM YYYY")&" · CONFIDENTIEL — CONSEILLER FINANCIER"
A2: ="Total portfolio: $"&TEXT('📈 PORTEFEUILLE'!C11,"#,##0")&" CAD · Gain total: +"&TEXT('📈 PORTEFEUILLE'!N11,"#,##0")&" ("&TEXT('📈 PORTEFEUILLE'!G11,"0.0%")") · USD/CAD: "&TEXT(CONFIG!B3,"0.0000") · Auto-calculé — Source: 📈 PORTEFEUILLE"
A4: 🎯 SCORECARD EXÉCUTIF
A5: MÉTRIQUE | B5: VALEUR | C5: CIBLE | D5: STATUT | E5: COMMENTAIRE CONSEILLER
A6: Portfolio Total CAD | B6: =TEXT('📈 PORTEFEUILLE'!C11,"$#,##0") | C6: $87,252 (ATH) | D6: =IF('📈 PORTEFEUILLE'!C11>87252,"🟢 NOUVEL ATH","🟡 "&TEXT(87252-'📈 PORTEFEUILLE'!C11,"$#,##0")&" de l'ATH") | E6: Correction mineure post-ATH 10 mars. Normale.
A7: Gain total (investi) | B7: =TEXT('📈 PORTEFEUILLE'!N11,"$#,##0")&" / "&TEXT('📈 PORTEFEUILLE'!G11,"0.0%") | C7: >15% | D7: =IF('📈 PORTEFEUILLE'!G11>0.15,"✅ SOLIDE","🟡 SOUS CIBLE") | E7: Performance supérieure au benchmark VFV.TO sur même période
A8: Expo USD | B8: =TEXT(CONFIG!B32,"0.0%") | C8: ≤65% | D8: =CONFIG!B47 | E8: Bien dans les limites. Marge $17,900 avant alerte.
A9: Expo IA estimée | B9: =TEXT(CONFIG!B31,"0.0%") | C9: ≤45% | D9: =IF(CONFIG!B31>0.45,"🔴 DÉPASSE 45%",IF(CONFIG!B31>0.4,"🟡 PROCHE","✅ OK")) | E9: Inclut SMH, AVGO, NVDA, QQQM, GEV, QTUM
A10: Tier 1 (conviction max) | B10: ="T1: "&TEXT(SUMIF('📋 MON PORTEFEUILLE'!D5:D43,"T1",'📋 MON PORTEFEUILLE'!J5:J43)/'📈 PORTEFEUILLE'!C11,"0.0%")&" / "&TEXT(SUMIF('📋 MON PORTEFEUILLE'!D5:D43,"T1",'📋 MON PORTEFEUILLE'!J5:J43),"$#,##0") | C10: >50% | D10: =IF(SUMIF('📋 MON PORTEFEUILLE'!D5:D43,"T1",'📋 MON PORTEFEUILLE'!J5:J43)/'📈 PORTEFEUILLE'!C11>0.5,"✅ CIBLE ATTEINTE","🟡 SOUS 50%") | E10: Excellente concentration sur les meilleures idées
A11: Tier 4 (dilution) | B11: ="T4: "&TEXT(SUMIF('📋 MON PORTEFEUILLE'!D5:D43,"T4",'📋 MON PORTEFEUILLE'!J5:J43)/'📈 PORTEFEUILLE'!C11,"0.0%")&" / "&TEXT(SUMIF('📋 MON PORTEFEUILLE'!D5:D43,"T4",'📋 MON PORTEFEUILLE'!J5:J43),"$#,##0") | C11: <15% | D11: =IF(SUMIF('📋 MON PORTEFEUILLE'!D5:D43,"T4",'📋 MON PORTEFEUILLE'!J5:J43)/'📈 PORTEFEUILLE'!C11<0.15,"✅ BON","🟡 À DILUER") | E11: REITs + ETFs défensifs: rôle cushion rempli
A12: Dividendes /an | B12: =TEXT(SUM('📋 MON PORTEFEUILLE'!P5:P43),"$#,##0")&" CAD" | C12: Croissant | D12: ✅ OK | E12: $160/mois — surtout T.TO, XEI, SRU.UN, ENB, TD
A13: Fonds urgence HISA | B13: =TEXT(CONFIG!B25,"$#,##0") | C13: $0 → $1,500/mois planifié | D13: =IF(CONFIG!B25>=15000,"✅ ATTEINT",IF(CONFIG!B25>0,"🟡 EN COURS","🔴 CRITIQUE")) | E13: 🟡 EN COURS — Prochaine paie → $1,500 EQ Bank EN PREMIER
A14: FHSA room restant | B14: =TEXT(CONFIG!B7,"$#,##0") | C14: Maximiser | D14: =IF(CONFIG!B7<1000,"⚠️ QUASI PLEIN",IF(CONFIG!B7<4000,"🟡 ACTION","✅ OK")) | E14: BdC 18 mars → opportunité achat VFV.TO pré-baisse taux
A15: Contributions auto | B15: NON | C15: $5,000/mois structuré | D15: 🔴 RISQUE | E15: 🟡 À AUTOMATISER avant 15 avril
A17: ⚠️ ANALYSE CONCENTRATION · Top positions & risques
A18: TICKER | B18: COMPTE | C18: VALEUR CAD | D18: % PORT. | E18: SEUIL ALERTE | F18: VERDICT CONSEILLER
A19: VFV.TO | B19: TFSA | C19: =TEXT('📋 MON PORTEFEUILLE'!J5,"$#,##0") | D19: =TEXT('📋 MON PORTEFEUILLE'!J5/'📈 PORTEFEUILLE'!C11,"0.0%") | E19: <25% | F19: ✅ Acceptable. Exposition S&P500 diversifiée par nature.
A20: TD.TO | B20: TFSA | C20: =TEXT('📋 MON PORTEFEUILLE'!J6,"$#,##0") | D20: =TEXT('📋 MON PORTEFEUILLE'!J6/'📈 PORTEFEUILLE'!C11,"0.0%") | E20: <10% T3 idéalement | F20: ⚠️ SURPONDÉRÉ pour un T3. Ne plus acheter. Diluer naturellement.
A21: SMH | B21: TFSA | C21: =TEXT('📋 MON PORTEFEUILLE'!J7,"$#,##0") | D21: =TEXT('📋 MON PORTEFEUILLE'!J7/'📈 PORTEFEUILLE'!C11,"0.0%") | E21: <15% | F21: ✅ Dans les limites. Semis = conviction validée.
A22: AVGO | B22: TFSA | C22: =TEXT('📋 MON PORTEFEUILLE'!J8,"$#,##0") | D22: =TEXT('📋 MON PORTEFEUILLE'!J8/'📈 PORTEFEUILLE'!C11,"0.0%") | E22: <15% | F22: ✅ T1 core. Accumuler si dip >5%.
A23: T3 Total | B23: Tous | C23: =TEXT(SUMIF('📋 MON PORTEFEUILLE'!D5:D43,"T3",'📋 MON PORTEFEUILLE'!J5:J43),"$#,##0") | D23: =TEXT(SUMIF('📋 MON PORTEFEUILLE'!D5:D43,"T3",'📋 MON PORTEFEUILLE'!J5:J43)/'📈 PORTEFEUILLE'!C11,"0.0%") | E23: <20% | F23: ⚠️ T3 légèrement surpondéré. Surtout dû à TD.TO.
A24: T.TO | B24: TFSA | C24: =TEXT('📋 MON PORTEFEUILLE'!J37,"$#,##0") | D24: =TEXT('📋 MON PORTEFEUILLE'!J37/'📈 PORTEFEUILLE'!C11,"0.0%") | E24: OK | F24: ⚠️ En perte -18.1%. NE PAS VENDRE (room TFSA). Surveiller dividende Q3.
A25: MFC.TO | B25: TFSA | C25: =TEXT('📋 MON PORTEFEUILLE'!J39,"$#,##0") | D25: =TEXT('📋 MON PORTEFEUILLE'!J39/'📈 PORTEFEUILLE'!C11,"0.0%") | E25: OK | F25: ⚠️ En perte -11.3%. NE PAS VENDRE. Règle absolue TFSA.
A27: ❄️ ANALYSE FISCALE · Optimisation snowball
A28: VÉHICULE | B28: COTISATION 2026 | C28: ÉCONOMIE IMPÔT | D28: COÛT RÉEL NET | E28: VALEUR @2042 (8%) | F28: STATUT
A29: REER SCHD | B29: $2,000 exécuté | C29: $1,060 (52.98%) | D29: $940 net | E29: ~$12,400 | F29: ✅ En cours · $2K/mois
A30: FHSA VFV.TO | B30: =TEXT(CONFIG!B33,"$#,##0")&" YTD" | C30: $6,357 (52.98%) | D30: $5,643 net | E30: ~$74,500 | F30: =IF(CONFIG!B7<1000,"⚠️ Room quasi plein","Room restant: $"&TEXT(CONFIG!B7,"#,##0"))
A31: TFSA AVGO | B31: $500/mois | C31: $0 (exonéré) | D31: $6,000/an | E31: ~$37,200 | F31: 🟡 Pas automatisé
A32: TOTAL 2026 | B32: ~$38,000/an dispo | C32: ~$18,400 économie | D32: ~$19,600 coût réel
A33: FTQ 2026 | B33: NON ÉLIGIBLE | C33: Revenu $140K > $129K | D33: $0 | F33: 🔴 Surveiller 2027
A35: 💼 RECOMMANDATIONS CONSEILLER · Priorité décroissante · 12 mars 2026
A36: PRIORITÉ | B36: TYPE | C36: ACTION | D36: ÉCHÉANCE | E36: RAISONNEMENT CONSEILLER
A37: 🔴 | B37: URGENT | C37: EQ Bank: ouvrir + $1,500/mois dès prochaine paie | D37: Cette semaine | E37: Risque opérationnel #1. Urgence médicale/voiture = zéro coussin. 20 min. eqbank.ca. Taux ~4.0% = $600/an.
A38: 🔴 | B38: URGENT | C38: Automatiser $5,000/mois le 15 de chaque mois | D38: Avant 15 avril | E38: Sans automatisation tu vas timer le marché. Biais documenté en session. Virement auto REER $2K + FHSA $1K + TFSA $500.
