Workbook

Sheet 🧠 CLAUDE CONTEXT
A1: 🧠 CLAUDE CONTEXT — Mémoire de session · Auto-généré · Ne pas modifier manuellement
A2: Uploader ce fichier à chaque session → Claude lit ce bloc en premier et reprend le contexte complet instantanément
A4: 📋 DERNIÈRE SESSION
A5: Version fichier | B5: v63-S39 | C5: Mis à jour automatiquement par Claude en fin de session
A6: Date session | B6: 13 mars 2026 | C6: HNE · Nunavik
A7: Prochaine session | B7: S36 — xlsx v59 + dashboard v16 + CLAUDE.md + data.json
A9: 📊 ÉTAT PORTFOLIO · 13 MARS 2026
A10: Total CAD | B10: ~$89,674 CAD (XEQT 100u confirmé · data.json 8h55 +$3,993) | C10: ATH: $87,252 · 10 mars 2026
A11: P&L ouvert | B11: +$13,469 CAD estimé · recalcul S36 avec data.json
A12: Coût de base | B12: $76,054.68
A13: TFSA | B13: $68,137 | C13: Dépôts: $51,500 · P&L +34.37%
A14: FHSA | B14: $18,772 CAD · XEQT 115u (100 FHSA + 25 TFSA) · VFV 16u FHSA | C14: XEQT 100u @$39.93 + VFV 16u · Objectif: $40,000
A15: REER | B15: $2,765 | C15: SCHD 64.3053u + JEPI 1u + cash $1.26 CAD
A16: USD/CAD | B16: 1.3702 | C16: Dynamique — fallback config
A17: Positions actives | B17: 40 — TFSA 26 · FHSA 12 · REER 2 | C17: TFSA 26 · FHSA 12 · REER 2
A18: USD exposition | B18: ~62% | C18: ✅ Sous seuil 65%
A20: 🔴 ACTIONS OUVERTES — PRIORITÉ S36
A21: 🔴 URGENT | B21: EQ Bank HISA — ouvrir compte | C21: $0 actuel → cible $15,000 · $1,500/mois automatique
A22: 🔴 URGENT | B22: Bénéficiaires Questrade | C22: TFSA + FHSA + REER sans bénéficiaires · ~$87K non protégé · 5 min
A23: 🔴 URGENT | B23: Automatiser $5,000/mois | C23: Avant 15 avril · REER $2K + FHSA $1K + TFSA $500 + EQ Bank $1.5K
A24: 🟡 IMPORTANT | B24: Post-BdC 18 mars → ZRE+XIC+VDU vers VFV.TO | C24: ~$1,878 à recycler de T4 vers T1 dans TFSA
A25: 🟡 IMPORTANT | B25: FHSA T4 trop élevé → recycler vers VFV.TO | C25: REI+SRU+XIC+XEI FHSA = $4,752 T4 · compte double exonération = max T1
A26: 📅 CALENDRIER | B26: Verdicts J+30 → 11 avril | C26: AVGO · SMH · GEV · SCHD · PLZ.UN · calculer alpha vs VFV.TO
A28: ✅ ACCOMPLI — S34-S35 · 13 MARS 2026
A29: ✅ Trade | B29: Research marché exhaustif mars 2026 complété (macro Iran/Fed/TSX + top 15 actions + 15 ETFs) | C29: TFSA qty=0 confirmé
A30: ✅ Trade | B30: XEQT.TO 100u @$39.93 FHSA exécuté 15:06:55 ET · décision modifiée 50/50 → 100% XEQT suite Research | C30: 13 mars 2026
A31: ✅ Dashboard | B31: portfolio_dashboard_v16.html | C31: Tickers cliquables · tri interactif · graphiques Chart.js jouables · 30 factsheets
A32: ✅ Dashboard | B32: xlsx v63-S39 | C32: Cerveau multi-piliers · CLAUDE CONTEXT · APPRENTISSAGE · CORPS · CULTURE · PROJET DE VIE
A33: ✅ Système | B33: CLAUDE CONTEXT intégré dans xlsx | C33: Onglet auto-généré · 0 upload manuel requis
A35: 🧠 DÉCISIONS & RAISONNEMENTS CLÉS
A36: Plan cotisation | B36: $5,000/mois confirmé S16 | C36: REER $2K + FHSA $1K + TFSA $500 + EQ Bank $1.5K · surplus libre $1,768/mois
A37: Snowball REER | B37: $2K/mois SCHD → ~$1,060 ARC remboursé | C37: 52.98% taux marginal Québec · mécanique clé
A38: FI objectif | B38: $2.1M = plancher · jamais plafond | C38: Liberté & optionalité · pas un chiffre fixe
A39: Maison 2030+ | B39: RAP $60K (REER) + FHSA $40K = $100K mise de fonds | C39: Solo · timeline révisée de 2028 à 2030+
A40: Psychologie | B40: Buy-the-dip T1 = conviction forte | C40: COVID 2020 ancre · -30%+ = ACHETER PLUS · frein = liquidités + timing
A42: ⚠️ RÈGLES ABSOLUES — Claude applique sans exception
A43: 🚫 JAMAIS | B43: Vendre T.TO ou MFC.TO dans TFSA | C43: Room de contribution perdu à jamais si vendu
A44: 🚫 JAMAIS | B44: Recréer le xlsx de zéro | C44: Toujours load_workbook — 2133 formules à préserver
A45: 🚫 JAMAIS | B45: Modifier xlsx sans autorisation explicite de Hey | C45: Demander "go" avant tout code
A46: ✅ TOUJOURS | B46: Vérifier room FHSA avant cotisation | C46: Room 2026 restant: ~$13,700
...

Sheet ⚙️ MASTER_INDEX
A1: Domaine | Source | Tier | Score | Statut | Lien/Accès
A2: Domaine | B2: Source | C2: Tier | D2: Score | E2: Statut | F2: Lien/Accès | H2: PROCHAIN VERDICT J+30
A3: FINANCE | B3: SEC EDGAR | C3: AAA | D3: 100 | E3: ACTIF | F3: sec.gov
A4: FINANCE | B4: Morningstar | C4: AAA | D4: 95 | E4: ACTIF | F4: morningstar.ca
A5: FINANCE | B5: Koyfin | C5: AAA | D5: 95 | E5: ACTIF | F5: koyfin.com
A6: FINANCE | B6: Bloomberg | C6: AAA | D6: 90 | E6: ACTIF | F6: bloomberg.com
A7: FINANCE | B7: Seeking Alpha | C7: AA | D7: 80 | E7: ACTIF | F7: seekingalpha.com
A8: ENTRAÎNEMENT | B8: Renaissance Periodization | C8: AAA | D8: 100 | E8: ACTIF | F8: renaissanceperiodization.com
A9: ENTRAÎNEMENT | B9: Stronger by Science | C9: AAA | D9: 95 | E9: ACTIF | F9: strongerbyscience.com
A10: ENTRAÎNEMENT | B10: Examine.com | C10: AAA | D10: 100 | E10: ACTIF | F10: examine.com
A11: ENTRAÎNEMENT | B11: PubMed | C11: AAA | D11: 100 | E11: ACTIF | F11: pubmed.ncbi.nlm.nih.gov
A12: ENTRAÎNEMENT | B12: Juggernaut Training | C12: AAA | D12: 90 | E12: ACTIF | F12: jtsstrength.com
A13: PARIS SPORTIFS | B13: KenPom | C13: AAA | D13: 100 | E13: ACTIF | F13: kenpom.com
A14: PARIS SPORTIFS | B14: Pinnacle | C14: AAA | D14: 95 | E14: ACTIF | F14: pinnacle.com
... A46: LIVRES | B46: Paris Review | C46: AAA | D46: 90 | E46: ACTIF | F46: theparisreview.org
A47: LIVRES | B47: Goodreads | C47: AA | D47: 80
A49: Domaine Source Tier Score Densité CORPS Journal of Strength & Cond. Res. AAA 90 Expansion CORPS Alan Aragon Research Review AAA 90 Expansion CORPS MASS (Stronger by Science) AAA 90 Expansion CORPS Examine.com AAA 90 Expansion CORPS Precision Nutrition AAA 90 Expansion CORPS Huberman Lab AA 85 Expansion CORPS Peter Attia (The Drive) AAA 90 Expansion CORPS Renaissance Periodization AAA 90 Expansion CORPS Juggernaut Training Systems AA 85 Expansion CORPS EliteFTS AA 85 Expansion CORPS Starting Strength AA 85 Expansion CORPS BarBend A 80 Expansion CORPS Breaking Muscle A 80 Expansion CORPS FRC (Functional Range Cond.) AA 85 Expansion CORPS BJJ Heroes A 80 Expansion CORPS Grappling Insider A 80 Expansion CORPS Chewjitsu A 80 Expansion CORPS FloGrappling A 80 Expansion CORPS Sleep Foundation AAA 90 Expansion CORPS Sports Medicine Journal AAA 90 Expansion CORPS PubMed AAA 90 Expansion CORPS Yoga Journal A 80 Expansion CORPS Human Kinetics AA 85 Expansion CORPS NSCA Journal AAA 90 Expansion CORPS Science of Sport AA 85 Expansion MAISON Harvard Business Review AAA 90 Expansion MAISON Atomic Habits (James Clear) AA 85 Expansion MAISON Deep Work (Cal Newport) AA 85 Expansion MAISON The Almanack of Naval Ravikant AAA 90 Expansion MAISON BiggerPockets AA 85 Expansion MAISON Canadian Real Estate Wealth AA 85 Expansion MAISON Statistique Canada (Logement) AAA 90 Expansion MAISON RateHub.ca AA 85 Expansion MAISON CMHC (Rapports Marché) AAA 90 Expansion MAISON Better Dwelling AA 85 Expansion MAISON ArchDaily A 80 Expansion MAISON Apartment Therapy A 80 Expansion MAISON House & Home Canada A 80 Expansion MAISON Todoist Productivity Blog A 80 Expansion MAISON Obsidian Forum (PKM) AA 85 Expansion MAISON Notion Academy A 80 Expansion MAISON The Minimalists A 80 Expansion MAISON Wait But Why AA 85 Expansion MAISON Seth Godin (Marketing/Strat) AAA 90 Expansion MAISON Deepstash A 80 Expansion MAISON Lifehacker (Performance) A 80 Expansion MAISON Medium (Productivité) A 80 Expansion MAISON Building a Second Brain (Forte) AA 85 Expansion MAISON Goodreads (Non-Fiction) A 80 Expansion MAISON Fast Company AA 85 Expansion CULTURE Foreign Affairs AAA 95 Expansion CULTURE Longform.org AAA 90 Expansion CULTURE The New Yorker AA 85 Expansion CULTURE Aeon Magazine AA 85 Expansion CULTURE The Atlantic AA 85 Expansion CULTURE The Paris Review AA 85 Expansion CULTURE Hardcore History (Dan Carlin) AAA 90 Expansion CULTURE Smithsonian Magazine AA 85 Expansion CULTURE JSTOR (Archive) AAA 90 Expansion CULTURE The School of Life AA 85 Expansion CULTURE Psychology Today AA 85 Expansion CULTURE Greater Good Science Center AA 85 Expansion CULTURE Criterion Collection (Cinéma) AA 85 Expansion CULTURE Sight & Sound AA 85 Expansion CULTURE MUBI A 80 Expansion CULTURE Letterboxd A 80 Expansion CULTURE Ars Technica AA 85 Expansion CULTURE Polygon (Culture) A 80 Expansion CULTURE Kotaku (Gaming Analysis) A 80 Expansion CULTURE History.com AA 85 Expansion CULTURE Nautilus AA 85 Expansion CULTURE The Marginalian AAA 90 Expansion CULTURE Lapham's Quarterly AA 85 Expansion CULTURE Philosophie Magazine AA 85 Expansion CULTURE The Economist (Culture) AAA 90 Expansion TECH/SYS Stratechery (Ben Thompson) AAA 95 Expansion TECH/SYS SemiAnalysis (Dylan Patel) AAA 95 Expansion TECH/SYS The Information AA 90 Expansion TECH/SYS NVIDIA Investor Relations AAA 95 Expansion TECH/SYS GitHub Documentation AAA 90 Expansion TECH/SYS Claude.ai Changelogs AAA 95 Expansion TECH/SYS Zapier Automation Blog AA 85 Expansion TECH/SYS Make.com Academy AA 85 Expansion TECH/SYS Reddit (r/selfhosted) A 80 Expansion TECH/SYS Reddit (r/automation) A 80 Expansion TECH/SYS TechCrunch AA 85 Expansion TECH/SYS Wired AA 85 Expansion TECH/SYS Stack Overflow AAA 90 Expansion TECH/SYS Google Apps Script Docs AAA 90 Expansion TECH/SYS AlphaSignal AAA 90 Expansion TECH/SYS TLDR Tech AA 85 Expansion TECH/SYS MIT Tech Review AAA 90 Expansion TECH/SYS Hacker News AAA 90 Expansion TECH/SYS Product Hunt A 80 Expansion TECH/SYS Docker Documentation AA 85 Expansion TECH/SYS Python Documentation AAA 90 Expansion TECH/SYS VS Code Docs AA 85 Expansion TECH/SYS Webflow University AA 85 Expansion TECH/SYS Claude.ai API Docs AAA 95
A50: "Note : Ce tableau est la base de mon S&P 200 par domaine. Chaque source est classée par Tier (AAA = Preuve scientifique/institutionnelle). Je demande une mise à jour trimestrielle du 'Score' basé sur la performance réelle de mes décisions."

Sheet 🚀 DÉMARRAGE
A1: 🚀 DÉMARRAGE CLAUDE · Portefeuille FI 2026 · v63-S39 · 13 mars 2026 · Glisser ce fichier → Session démarre automatiquement | B1: 🚀 DÉMARRAGE CLAUDE · Portefeuille FI 2026 · v63-S39 · 13 mars 2026
B2: "Lis du haut vers le bas → web search → ta 1ʳᵉ réponse = les 3 points les plus importants. Zéro question de contexte."
A4: 📊 SNAPSHOT PORTFOLIO · Soir 13 mars 2026 · Source: Questrade confirmé
B5: COMPTE | C5: VALEUR CAD | D5: P&L $ | E5: P&L % | F5: INVESTI | G5: ACTIONS URGENTES
A6: TFSA 📈 | B6: ='📈 PORTEFEUILLE'!C8 -> 67855.03 | C6: 68072.95 | D6: ='📈 PORTEFEUILLE'!G8 -> 0.27599876 | E6: ='📈 PORTEFEUILLE'!E8 -> 48896.466 | F6: VFV.TO $1,000/mois · room $13,700 restant
A7: FHSA 🏠 | B7: ='📈 PORTEFEUILLE'!C9 -> 14767.018 | C7: 18816.32 | D7: ='📈 PORTEFEUILLE'!G9 -> 0.17283197 | E7: ='📈 PORTEFEUILLE'!E9 -> 12199.675 | F7: SCHD ✅ 64.3053u · +$1,060/mois ARC · Prochain: $2,000 le 12 mars
A8: REER ❄️ | B8: ='📈 PORTEFEUILLE'!C10 -> 2764.1683 | C8: 2798.09 | D8: ='📈 PORTEFEUILLE'!G10 -> 0.39485295 | E8: ='📈 PORTEFEUILLE'!E10 -> 1694.3566 | F8: ✅ SCHD $2,000 REER exécuté · 64.3053u @ $30.80
A9: ▼ TOTAL | B9: ='📈 PORTEFEUILLE'!C11 -> 85386.216 | C9: 89687.36 | D9: 16572.89 | E9: 0.1762
A10: 📊 Ref YTD | B10: $74,290 CAD (est. 1 jan 2026) | E10: VFV YTD: -1.57% | G10: Alpha: ⬜ Calculer
A11: 📈 Perf 1 an
A14: 🚨 ACTIONS URGENTES · Coût d'inaction réel chaque jour
B15: # | C15: ACTION | E15: ÉCHÉANCE | F15: STATUT
B16: ✅ FAIT — SCHD $2,000 REER exécuté 12 mars · 64.3053u confirmés | C16: SCHD $2,000 REER → 12 mars 9h30 HNE | E16: +$1,060/mois ARC (52.98%×$2K) | F16: 12 mars AM | G16: ✅ EXÉCUTÉ — 64.3053u confirmé Questrade
B17: 🟡 EN COURS — Ouvrir EQ Bank + virer $1,500 dès prochaine paie cette semaine | C17: 10 mois → $15,000 atteint · AVANT Questrade dès que paie rentre | E17: Risque opérationnel éliminé | F17: ASAP | G17: PAS OUVERT
B18: 🟡3 | C18: ZRE+XIC+VDU TFSA ~$1,878 → T1 | E18: ~$1,878 T4→T1 + exposition IA+ | F18: Post-BdC 18 mars | G18: EN ATTENTE
B20: 📅5 | E20: Calendrier macro + earnings
A22: ⚡ PROTOCOLE SESSION · Dans l'ordre · 10 minutes max · voir Section 11 pour détail
A23: 🔥 1 | B23: Aspects #1+#2 uploadés · #3 taux USD/CAD → CONFIG!B3 · #4 trades faits | E23: CRITIQUE · Section 14 pour guide uploads
A24: 🔥 2 | B24: VALIDATION → ÉTAT GLOBAL = 🟢 · si 🔴 → corriger avant de continuer | E24: 2 min max
A25: 🔥 3 | B25: Snapshot → #5 cash · #6 cotisations YTD · #12 pending session précédente | E25: Confirmer positions + buying power
A26: ⭐ 4 | B26: Dire: #8 intention · #9 trades envisagés · #13 calendrier · #14 dividendes | E26: 3 phrases · voir template Section 11
A27: ⭐ 5 | B27: Claude applique: #7 macro (web search auto) · #11 benchmark · R1→R13 | E27: Automatique · aucune action
A29: 🎯 PLAN D'EXÉCUTION IMMÉDIAT · 3 actions · Chaque jour de retard = argent perdu
A30: 🔴 ACTION #1 — SCHD $2,000 REER · DEMAIN 12 mars · 9h30 HNE pile à l'ouverture
A31: ÉTAPE | B31: Ouvrir Questrade → REER #52924767 → Acheter SCHD
A32: MONTANT | B32: $2,000 CAD ordre → ~$1,475 USD au taux ~1.3559
A33: ORDRE
A34: IMPACT IMMÉDIAT | B34: +$1,060/mois ARC (remboursé en ~6 semaines après déclaration)
A35: COÛT INACTION
A36: APRÈS | B36: MAJ CONFIG!B34 (REER YTD: 0→2000) + noter dans JOURNAL DÉCISIONS
A38: 🔴 ACTION #2 — EQ Bank HISA $15,000 · Cette semaine · ~20 min en ligne
A39: SITE | B39: eqbank.ca → Ouvrir un compte épargne → taux ~4.0% (confirmer live)
A40: VIREMENT
A41: RÔLE | B41: Fonds urgence exclusivement · ne pas investir · ne pas toucher
A42: POURQUOI | B42: Risque opérationnel #1 — si urgence médicale/équipement/voiture = zéro stress
A43: RENDEMENT
A44: APRÈS | B44: MAJ CONFIG!B25 (HISA → $15,000) + mettre à jour ALERTES section fonds urgence
A46: 📅 ACTION #3 — Verdicts J+30 · 11 avril 2026 · Mettre une alarme maintenant
A47: DATE EXACTE | B47: 11 avril 2026 — mettre alarme téléphone MAINTENANT
A48: DURÉE | B48: ~30 min · ouvrir Questrade · noter prix de chaque ticker du 11 mars
...

Sheet 🧠 PROFIL
B1: 🧠 PROFIL INVESTISSEUR · Source de vérité sur TOI · Mis à jour annuellement
B2: Ce document = la mémoire de qui tu es en tant qu'investisseur. Claude le lit en priorité à chaque session.
B4: 👤 IDENTITÉ FINANCIÈRE
B5: Âge actuel | C5: =CONFIG!B4 | D5: ←auto | E5: ans
B6: Revenu brut annuel | C6: 140000 | D6: ⬜ Confirmer avec T4 2025 | E6: CAD
B7: Revenu NET estimé /mois | C7: 7950 | D7: ← $3,000 × 26 ÷ 12 + $1,450 prime Nunavik · Confirmé S16 | E7: CAD/mois
B8: Dépenses fixes /mois | C8: 1182 | D8: Épicerie $400 + Tél $110 + Voiture $275 + Ass.auto $100 + Ass.moto $80 + Essence $50 + Abo $25 + Loisirs $50 + Voyages $42 + Vêt $50 · MAJ S16 | E8: CAD/mois
B9: Capacité épargne réelle /mois | C9: =C7-C8 -> 6768 | D9: ← Calculé automatiquement | E9: CAD/mois
B10: Contributions investissement | C10: 5000 | D10: REER $2K + FHSA $1K + TFSA $500 + EQ Bank $1,500 · Plan confirmé S16 | E10: CAD/mois
B11: Surplus non investi /mois | C11: =C9-C10 -> 1768 | D11: ← Tampon / extra / imprévus | E11: CAD/mois
B12: Taux marginal QC | C12: =CONFIG!B11 -> 0.5298 | D12: ←auto CONFIG | E12: %
B13: Zone géographique | C13: Nunavik QC | D13: Avantages: logement+bouffe gratuits · Désavantage: isolement, mobilité réduite
B14: Situation couple | C14: En couple | D14: Finances 100% séparées · achat maison solo prévu
B15: Régime retraite employeur | C15: =CONFIG!B30 -> AUCUN | D15: ←auto CONFIG
B17: 🎯 PROFIL DE RISQUE · Réponses honnêtes · Ne pas idéaliser
B18: Tolérance drawdown maximale | C18: -30% à -40% | D18: Basé sur comportement COVID 2020 : achat agressif à -35%. Au-delà de -40% sur portfolio total = zone inconnue. | E18: 🟠 AGRESSIF
B19: Réaction prouvée en crise | C19: ACHAT MASSIF | D19: COVID mars 2020 : positions achetées pendant le crash. Comportement documenté, pas théorique. | E19: ✅ VALIDÉ
B20: Scénario qui te ferait vraiment vendre | C20: ⬜ À documenter | D20: Ex: perte emploi simultanée + drawdown -40% + urgence médicale. Quel est ton vrai point de rupture ? | E20: ⬜ DÉFINIR
B21: Horizon d'investissement réel | C21: 2043 (FI) + 20 ans après | D21: ~17 ans jusqu'à FI potentiel, puis 30+ ans de décaissement. Horizon total = 47 ans. | E21: ✅ LONG TERME
B22: Acceptation volatilité mensuelle | C22: ±$5,000-8,000 CAD | D22: Portfolio $87K × 8% volatilité mensuelle typique ≈ ±$7K. Confortable ? | E22: ⬜ CONFIRMER
B23: Biais comportementaux identifiés | C23: Buy-the-dip fort · FOMO possible sur IA | D23: Forces: discipline achat en crise. Risques: surpondération IA sans discipline de seuil. | E23: ⚠️ SURVEILLER
B24: Score risque objectif (1-10) | C24: 8 | D24: 8/10 = profil agressif orienté croissance. Justifié par horizon 17+ ans et épargne high-rate. | E24: 🔴 AGRESSIF
B26: 🆘 STRESS-TEST · Que se passe-t-il si... · Plan B pour chaque scénario
B27: SCÉNARIO | C27: IMPACT ESTIMÉ | D27: PLAN B ACTIVÉ | E27: SEUIL DÉCLENCHEUR
B28: Perte d'emploi 12 mois | C28: Zéro revenu · dépenses fixes $700/mois seulement · portfolio intact | D28: EQ Bank $15K (7 mois) · stop contributions · vendre ZRE+XIC+VDU T4 si besoin | E28: Chômage confirmé
B29: Marché -30% (ex: récession 2025) | C29: Portfolio $87K → ~$61K · P&L TFSA effacé | D29: ACHAT AGRESSIF T1 · doubler contributions si cash dispo · NE PAS vendre | E29: S&P500 -20% depuis ATH
B30: Marché -40% (ex: 2008-09) | C30: Portfolio $87K → ~$52K · AVGO/SMH/GEV potentiellement -50% | D30: Même plan: acheter · vérifier qu'aucun titre n'est en danger fondamental · tenir | E30: VIX > 40
B31: Invalidité permanente | C31: ✅ Couverture COMPLÈTE employeur · Assurance vie: employeur + privée ✅ | D31: 🔴 Bénéficiaires TFSA/REER/FHSA NON DÉSIGNÉS — ACTION: Questrade → Mon compte → Bénéficiaires | E31: Diagnostic médical
B32: Décès (planification successorale) | C32: TFSA → conjoint/bénéficiaire tax-free · REER → succession imposable | D32: ⬜ DÉFINIR: bénéficiaires TFSA/REER/FHSA · testament à jour | E32: N/A — prévenir maintenant
B33: Taux hypothécaires > 7% en 2030 | C33: Paiement mensuel $400K @7% = $2,798/mois vs $1,222 @4.5% | D33: Revoir décision maison · attendre baisse taux · augmenter mise de fonds | E33: Taux 5 ans > 6%
B35: 📉 INFLATION · $2.1M en 2043 ≠ $2.1M aujourd'hui · Impact réel modélisé
B36: Taux inflation hypothèse | C36: 0.025 | D36: Inflation Canada historique ~2.0-2.5%. BdC cible = 2%.
B37: Années jusqu'à FI (Scénario B) | C37: 21 | D37: 2026 → 2047 (FI 55 ans, confirmé S16)
B38: Objectif FI nominal ($) | C38: =CONFIG!B20 -> 2100000 | D38: ←auto CONFIG
B39: ⚠️ Objectif FI RÉEL ajusté inflation | C39: =C38*(1+C36)^C37 -> 3527121.9 | D39: ← En dollars 2043 pour MÊME pouvoir d'achat qu'aujourd'hui
B40: Écart vs objectif nominal | C40: =C39-C38 -> 1427121.9 | D40: ← Combien il manque par rapport à $2.1M nominal · Ajuster la cible FI en conséquence
B41: Revenu mensuel équivalent en 2043 | C41: =C38*(1+C36)^C37*0.04/12 -> 11757.073 | D41: ← Règle 4% sur objectif ajusté = revenu mensuel réel équivalent à $7K/mois 2026
B43: 💎 PATRIMOINE NET TOTAL · Au-delà du portfolio · Bilan complet
B44: ACTIF | C44: VALEUR CAD | D44: NOTE | E44: LIQUIDITÉ
B45: TFSA | C45: ='📈 PORTEFEUILLE'!L44 -> 67855.03 | D45: ←auto · Investissement long terme | E45: 🔴 Intouchable
...

Sheet 📓 JOURNAL DÉCISIONS
B1: 📓 JOURNAL DÉCISIONS · Apprentissage continu · Ne jamais répéter la même erreur deux fois
B2: "Chaque décision documentée = Claude apprend. Résultat J+30 obligatoire. Dans 6 mois ce journal = meilleur atout."
A4: 📋 LOG DÉCISIONS · Saisir après chaque transaction ou décision importante
B5: DATE | C5: TICKER | D5: COMPTE | E5: ACTION | F5: MONTANT | G5: PRIX | H5: RATIONALE | I5: RÉSULTAT J+30 | J5: DELTA % | K5: LEÇON | L5: VERDICT
B6: 2026-03-11 | C6: AVGO | D6: TFSA | E6: ACHETÉ | F6: ~$462 | G6: $340.95 | H6: Soir · buying power settle · 1u fractionnel · DCA opportuniste | I6: ⬜ À remplir 11 avr 2026
B7: 2026-03-11 | C7: GEV | D7: TFSA | E7: ACHETÉ | F7: ~$314 | G7: $845.53 | H7: Soir · fractionnel · énergie IA · position stratégique renforcée | I7: ⬜ À remplir 11 avr 2026
B8: 2026-03-11 | C8: SMH | D8: TFSA | E8: ACHETÉ | F8: ~$2,715 | G8: $400.33 | H8: 13h55 · T4→T1 · semi-conducteurs · dip session · +5u | I8: ⬜ À remplir 11 avr 2026
B9: 2026-03-11 | C9: AVGO | D9: TFSA | E9: ACHETÉ | F9: ~$2,772 | G9: $340.65 | H9: 13h34 · T4→T1 · IA chips · redéploiement PLZ.UN · +6u | I9: ⬜ À remplir 11 avr 2026
B10: 2026-03-11 | C10: GEV | D10: TFSA | E10: ACHETÉ | F10: ~$1,144 | G10: $844.18 | H10: 13h37 · T4→T1 · énergie IA infrastructure · +1u | I10: ⬜ À remplir 11 avr 2026
B11: 2026-03-11 | C11: REI.UN.TO | D11: TFSA | E11: VENDU | F11: $6,315 | G11: $19.02 | H11: 13h54 · T4→T1 · REIT résidentiel sous-pression taux élevés | I11: ✅ Capital redéployé SMH | J11: REITs TFSA → dilution naturelle confirmée
B12: 2026-03-11 | C12: PLZ.UN.TO | D12: TFSA | E12: VENDU | F12: $4,094 | G12: $4.26 | H12: 13h33 · T4→T1 · en gain +17% · REIT sous-performant vs T1 | I12: ✅ Capital redéployé AVGO+GEV | J12: Vendre T4 en gain = bon timing
B13: 2026-03-10 | C13: VFV.TO | D13: FHSA | E13: ACHETÉ | F13: ~$2,518 | G13: $157.38 | H13: Premier achat FHSA 2026 · double exonération fiscale · ancre CAD | I13: ⬜ À remplir 10 avr 2026
B14: 2026-03-09 | C14: AVGO | D14: TFSA | E14: ACHETÉ | F14: ~$197 | G14: $345.76 | H14: DCA mensuel fractionnel · T1 · bull case IA confirmé Q1 | I14: ⬜ À remplir 9 avr 2026
A16: ── NOUVELLES DÉCISIONS — AJOUTER ICI ──
B18: 2026-03-11 | C18: SMH ×10u | D18: TFSA | E18: ACHETÉ | F18: ~$5,434 | G18: $400.33-67 | H18: 10u en 2 tranches · diversification dip vs AVGO only | I18: ⬜ J+30 | J18: ⬜ Leçon | K18: ✅ Bon conseil · diversifier | L18: ⬜ Verdict
B19: 2026-03-09 | C19: Grande rotation | D19: TFSA | E19: MULTI | F19: ~$26K | G19: Varié | H19: Liquidation 15+ positions → T1 concentré · SESSION MAJEURE | I19: ⬜ J+30 | J19: ⬜ Leçon | K19: ✅ Rotation validée · excellent | L19: ⬜ Verdict
B20: 2026-03-09 | C20: SCHD ×2 | D20: REER | E20: ACHETÉ | F20: ~$222 USD | G20: $30.88-30.94 | H20: REER débloqué · 2 tranches · snowball ARC | I20: ⬜ J+30 | J20: ⬜ Leçon | K20: ✅ Priorité #1 · parfait | L20: ⬜ Verdict
B21: 2026-03-09
B22: 2026-03-04 | C22: ZLB.TO | D22: TFSA | E22: ACHETÉ | F22: $240 | G22: $59.97 CAD | H22: GTC · +4u Low Vol T3 · stabilité | I22: ⬜ J+30 | J22: ⬜ Leçon | K22: ⬜ À évaluer J+30 | L22: ⬜ Verdict
B23: 2026-03-03 | C23: H.TO | D23: TFSA | E23: ACHETÉ | F23: $407 | G23: $58.08 CAD | H23: GTC · +7u Hydro One T3 · utilités défensif | I23: ⬜ J+30 | J23: ⬜ Leçon | K23: ⬜ À évaluer J+30 | L23: ⬜ Verdict
B24: 2026-02-09 | C24: MFC.TO | D24: TFSA | E24: ACHETÉ | F24: $414 | G24: $51.70 CAD | H24: GTC · +8u Manulife · règle JAMAIS VENDRE active | I24: ⬜ J+30 | J24: ⬜ Leçon | K24: ⬜ À évaluer J+30 | L24: ⬜ Verdict
B25: YYYY-MM-DD | C25: TICKER | D25: CTE | E25: ACHETÉ/VENDU | F25: $ | G25: $ | H25: Pourquoi cette décision? | I25: ⬜ À remplir J+30 | J25: Leçon apprise? | K25: Conseil donné par Claude au moment du trade | L25: ⬜ Bon / Mauvais · pourquoi
B29: 💡 VERDICT J+30 : Remplir "✅ Bon · [raison]" ou "❌ Mauvais · [raison]" · Ce sont les données qui améliorent Claude session après session
A36: 🧠 PATTERNS COMPORTEMENTAUX · Reconnus par Claude · Mis à jour chaque session
B37: ID | C37: PATTERN | E37: DESCRIPTION
B38: P1 | C38: Buy the dip | E38: Achat systématique en correction · COVID playbook · jamais paniquer · AVGO -10% = achète plus
B39: P2 | C39: Timing mi-mois | E39: Liquidités arrivent mi-mois pas début · planifier achats en conséquence · pas de FOMO
B40: P3 | C40: Sessions intensives | E40: Sessions longues et profondes (vacances) vs courtes quotidiennes · adapter profondeur analyse
B41: P4 | C41: Rotation T4→T1 | E41: Rotation T4→T1 quand T4 en gain >5% · ne jamais attendre le top · agir quand gain visible
B42: P5 | C42: Fiscal first | E42: REER avant TFSA si même ticker · 52.98% retour immédiat · règle non négociable
B45: 📅 PRÉPARATION VERDICTS J+30 · À remplir le 11 avril 2026 · Évaluer chaque trade du 11 mars
B46: ⏰ Le 11 avril 2026 — ouvrir ce tableau, regarder prix Questrade de chaque ticker, remplir col I+J+K
B47: TICKER | C47: COMPTE | D47: PRIX ACHAT | E47: QTÉ | F47: DATE TRADE | G47: PRIX J+30 (11 avr) | H47: PERF 30j | I47: VERDICT CLAUDE (bon/mauvais?) | J47: LEÇON | K47: SCORE CLAUDE
B48: PLZ.UN.TO | C48: TFSA | D48: $4.26 CAD | E48: 961u | F48: 2026-03-11 | G48: ⬜ Prix J+30 | H48: VENDU | I48: ✅ Bon — T4 en gain +17% → T1 | J48: ⬜ | K48: —
B49: REI.UN.TO | C49: TFSA | D49: $19.02 CAD | E49: 332u | F49: 2026-03-11 | G49: ⬜ Prix J+30 | H49: VENDU | I49: ✅ Bon — timing pre-BdC ok | J49: ⬜ | K49: —
B50: AVGO | C50: TFSA | D50: $340.65 USD | E50: 6u | F50: 2026-03-11 | G50: ⬜ Prix J+30 | H50: ⬜ | I50: ✅ Probable — T1 IA core | J50: ⬜ | K50: ⬜
B51: GEV | C51: TFSA | D51: $844.18 USD | E51: 1u | F51: 2026-03-11 | G51: ⬜ Prix J+30 | H51: ⬜ | I51: ✅ Probable — énergie IA | J51: ⬜ | K51: ⬜
B52: SMH ×5 | C52: TFSA | D52: $400.33 USD | E52: 5u | F52: 2026-03-11 13h55 | G52: ⬜ Prix J+30 | H52: ⬜ | I52: ✅ Probable — semis dip | J52: ⬜ | K52: ⬜
B53: SMH ×5 | C53: TFSA | D53: $400.67 USD | E53: 5u | F53: 2026-03-11 14h02 | G53: ⬜ Prix J+30 | H53: ⬜ | I53: ✅ Probable — 2e tranche | J53: ⬜ | K53: ⬜
B54: AVGO soir | C54: TFSA | D54: $340.19 USD | E54: ~1u | F54: 2026-03-11 soir | G54: ⬜ Prix J+30 | H54: ⬜ | I54: ⬜ À évaluer — buying power settle | J54: ⬜ | K54: ⬜
...

Sheet 🧠 RAISONNEMENTS
A1: 🧠 RAISONNEMENTS & PSYCHOLOGIE · Le POURQUOI des décisions · Mémoire comportementale cumulée · S21
A2: 📌 Ce qui compte n'est pas QUOI tu as acheté, mais POURQUOI — et si ce pourquoi était bon. Chaque ligne = une leçon permanente.
A3: ① BIAIS PSYCHOLOGIQUES DOCUMENTÉS · Identifiés en session · Pattern recognition cumulatif
A4: BIAIS | B4: DESCRIPTION | C4: MANIFESTATION RÉELLE | D4: DÉCLENCHEUR | E4: STRATÉGIE CONTRE | F4: STATUT | G4: SESSIONS
A5: Buy-the-dip fort ✅ | B5: Achat agressif pendant corrections | C5: COVID mars 2020 : achat à -35% → retour exceptionnel. 11 mars 2026 : AVGO+SMH+GEV achetés pendant correction -3.4%. | D5: VIX > 20, S&P -5%+ depuis ATH | E5: Ancrer sur historique COVID. Calculer valeur à 10 ans. | F5: ✅ FORCE | G5: S1→S21
A6: Frein pré-achat ⚠️ | B6: Hésitation 1-3 jours avant achat même en conviction max | C6: AVGO 11 mars : 2 jours d'hésitation. Peur d'acheter trop tôt dans la correction. | D6: Incertitude marché en cours | E6: Pre-commit : décider le soir, exécuter à l'ouverture. | F6: ⚠️ ACTIF | G6: S18-S21
A7: FOMO IA possible ⚠️ | B7: Surpondération secteur IA par enthousiasme | C7: Expo IA ~35% coût base. Documenté comme risque toutes les sessions. | D7: Nouvelles IA · perf AVGO/SMH | E7: Règle absolue ≤45%. Calculer expo avant chaque achat T1 IA. | F7: ⚠️ ACTIF | G7: S14→S21
A8: Inaction sur urgences 🔴 | B8: Retarder actions simples malgré documentation répétée | C8: EQ Bank $0 après 4+ sessions. Bénéficiaires non désignés. Automatisation non faite. | D8: Sentiment que c'est moins urgent que les trades | E8: Lier action urgente à prochaine paie. Alarme téléphone. | F8: 🔴 CRITIQUE | G8: S17→S21
A9: Timing parfait ⚠️ | B9: Attendre le meilleur moment au lieu de DCA systématique | C9: Contributions non automatisées → risque timer le marché chaque mois. | D9: Volatilité · incertitude macro | E9: Automatiser le 15 de chaque mois. | F9: ⚠️ ACTIF | G9: S16→S21
A11: ② JOURNAL DES RAISONNEMENTS · Décisions clés avec le POURQUOI réel · Verdict J+30 intégré
A12: DATE | B12: TICKER | C12: ACTION | D12: ÉMOTION | E12: RAISONNEMENT RÉEL | F12: DOUTES AU MOMENT | G12: VERDICT J+30 | H12: LEÇON APPRISE
A13: 2026-03-11 | B13: AVGO | C13: 🟢 ACHETÉ | D13: Conviction + légère hésitation | E13: T1 core IA. Dip -3.4% ATH. VIX 24.6. Broadcom = quasi-monopole switch semis IA. Prix $340.65 = -15% depuis ATH. | F13: Trop tôt dans la correction? Attendre -20%? | G13: ⬜ 11 avril 2026 | H13: Hésitation = frein pré-achat actif. Conviction fondamentale = correcte. Pre-commit aurait éliminé 2 jours d'attente.
A14: 2026-03-11 | B14: SMH ×2 | C14: 🟢 ACHETÉ | D14: Conviction forte | E14: ETF semis = expo T1 sans risque titre unique. NVDA+AVGO+TSM sans concentration. VIX élevé = opportunité. | F14: Double position trop agressif? | G14: ⬜ 11 avril 2026 | H14: Double achat ETF = bon si conviction sectorielle. Moins risqué qu'un titre seul. À refaire en correction.
A15: 2026-03-11 | B15: GEV | C15: 🟢 ACHETÉ | D15: Conviction forte | E15: Infrastructure IA + énergie propre. Croissance >30%/an. Complémentaire AVBO/SMH. Small position = risque contrôlé. | F15: Valorisation élevée? Cyclique? | G15: ⬜ 11 avril 2026 | H15: Position initiée à conviction. Petite taille = entrée prudente. Accumuler si confirmation.
A16: 2026-03-11 | B16: PLZ.UN | C16: 🔴 VENDU | D16: Soulagement rationnel | E16: T4 REIT faible croissance. Libérer capital T1. Décision système, pas émotionnelle. $4,094 recyclés. | F16: Vendre en correction = bon timing? | G16: ✅ Correct | H16: Rotation T4→T1 = décision système pure. Résultat: $4,094 → AVGO+SMH+GEV. À reproduire systématiquement.
A17: 2026-03-12 | B17: SCHD | C17: 🟢 ACHETÉ | D17: Discipline pure — zéro émotion | E17: REER $2,000 → SCHD. Planifié S19. Exécuté 9h30 HNE. Snowball $1,060/mois ARC activé. | F17: Aucun — pré-commité la veille | G17: ✅ Parfait | H17: Pre-commitment = zéro hésitation. Meilleur trade = décidé avant l'ouverture. Modèle à reproduire.
A19: ③ PATTERNS RÉCURRENTS · Ce que les données révèlent sur le style décisionnel
A20: PATTERN | B20: FRÉQUENCE | C20: IMPACT | D20: VERDICT GLOBAL
A21: Buy-the-dip systématique | B21: Chaque correction >3% → achat T1 | C21: Très positif — retours supérieurs au DCA fixe 2020-2026 | D21: ✅ GARDER — C'est l'avantage compétitif principal
A22: Pre-commitment = zéro friction | B22: SCHD 12 mars = zéro hésitation vs AVGO 11 mars = 2 jours | C22: Pré-décider = exécution parfaite sans stress | D22: ✅ SYSTÉMATISER — Décider le soir, exécuter à l'ouverture
A23: Inaction sur non-trades | B23: EQ Bank, automatisation, bénéficiaires = toujours reportés | C23: Risque opérationnel cumulatif élevé | D23: 🔴 PATTERN DANGEREUX — Alarme téléphone = seule solution
A24: Validation Claude = accélérateur | B24: Sessions Claude → décisions plus rapides et plus sûres | C24: Frein pré-achat réduit de 80% | D24: ✅ CONTINUER — Valeur principale des sessions
A26: ④ RÈGLES PSYCHOLOGIQUES PERSONNELLES · Validées par expérience réelle · Gravées S21
A27: CODE | B27: NOM | C27: RÈGLE COMPLÈTE | I27: STATUT
A28: R-PSY-01 | B28: Ancre COVID 2020 | C28: En crise → rappeler : mars 2020, tu as acheté à -35% → retour exceptionnel. Même playbook toujours. | I28: ✅ Actif S1
A29: R-PSY-02 | B29: Pre-commitment obligatoire | C29: Décider le soir QUOI et COMBIEN. Exécuter à l'ouverture sans revoir la décision. | I29: ✅ Actif S20
A30: R-PSY-03 | B30: Émotion = signal, pas décision | C30: Si FOMO → reculer. Si peur → vérifier fondamentaux. Émotion = information, jamais instruction. | I30: ✅ Actif S18
A31: R-PSY-04 | B31: Urgences = alarme téléphone | C31: EQ Bank, bénéficiaires, automatisation → alarme téléphone immédiatement, pas 'tantôt'. | I31: 🔴 À implémenter
A32: R-PSY-05 | B32: Validation externe = accélérateur | C32: Partager le raisonnement avec Claude avant d'exécuter réduit le frein de 80%. | I32: ✅ Actif S16
B33: Infrastructure avant contenu | C33: Récurrent | D33: On construit de beaux outils mais les onglets restent vides | E33: ⚠️ À surveiller — nourrir le cerveau à chaque session
A35: S34 · 13 mars 2026 · DÉCISION FHSA $4,015
A36: CONTEXTE | B36: Marché en correction –4.6% depuis ATH jan 2026. Iran/pétrole. Fed bloquée. Cash FHSA $4,015 disponible.
A37: ANALYSE RÉALISÉE | B37: Top 15 actions Questrade + Top 15 ETFs canadiens analysés. Comparaison 3 options (100% VFV / 50-50 / 100% XEQT).
A38: CONCLUSION ANALYSE | B38: Aucune action individuelle appropriée pour FHSA (risque concentré, compte maison 2030). VFV.TO + XEQT.TO = meilleurs ETFs pour profil.
A39: PLAN RETENU | B39: 100% XEQT.TO · 100 unités @$39.93 · $3,993 CAD
A40: RATIONALE | B40: VFV = continuité + track record. XEQT = comble vide intl. Sharpe XEQT 1.46 > VFV 0.83. USD reste ≤65%. Deux gratuits Questrade.
A41: DEVIL'S ADVOCATE | B41: 100% VFV surperforme long terme (10+ ans) mais concentre encore plus en US dans compte déjà à 62% USD.
A42: VERDICT J+30 | B42: 13 avril 2026 · comparer XEQT.TO vs VFV.TO et vs portefeuille S&P 500 pur
A43: STATUT | B43: ✅ EXÉCUTÉ — 13 mars 2026 · 15:06:55 ET
A45: S36 · 13 mars 2026 · AUDIT SYSTÈME APPRENTISSAGE
...

Sheet 📋 MON PORTEFEUILLE
A1: 📋 MON PORTEFEUILLE · LIVE via formules · Mise à jour auto depuis 📈 PORTEFEUILLE · Trier: cliquer sur les en-têtes ▲▼
A2: ="💰 Total: $"&TEXT('📈 PORTEFEUILLE'!C11,"#,##0")&" CAD" -> 💰 Total: $85,386 CAD | E2: 📈 Gain: +$14,788 (20.6%) | I2: 💵 Div/an: $1,926 CAD | L2: 📊 39 positions · TFSA + FHSA + REER | O2: 🇺🇸 USD: 44.8% 🇨🇦 CAD: 55.2%
A3: 🟢 T1 = Conviction max — Accumuler | E3: 🟡 T2 = Accumuler sélectivement | I3: 🟠 T3 = Garder, ne plus acheter | M3: ⬜ T4 = Diluer naturellement
A4: TICKER ▲▼ | B4: NOM ▲▼ | C4: TYPE ▲▼ | D4: TIER ▲▼ | E4: COMPTE ▲▼ | F4: QTÉ ▲▼ | G4: PRIX ACT ▲▼ | H4: DEV ▲▼ | I4: PRIX CAD ▲▼ | J4: VALEUR CAD ▲▼ | K4: INVESTI CAD ▲▼ | L4: GAIN $CAD ▲▼ | M4: GAIN % ▲▼ | N4: % PORT. ▲▼ | O4: YIELD % ▲▼ | P4: DIV/AN CAD ▲▼ | Q4: DIV/MOIS ▲▼ | R4: SIGNAL ▲▼
A5: ='📈 PORTEFEUILLE'!B15 -> VFV.TO | B5: ='📈 PORTEFEUILLE'!C15 -> Vanguard S&P 500 | C5: ='📈 PORTEFEUILLE'!D15 -> ETF | D5: ='📈 PORTEFEUILLE'!E15 -> T1 | E5: ='📈 PORTEFEUILLE'!F15 -> TFSA | F5: ='📈 PORTEFEUILLE'!G15 -> 84 | G5: ='📈 PORTEFEUILLE'!I15 -> 161.8 | H5: ='📈 PORTEFEUILLE'!K15 -> CAD | I5: ='📈 PORTEFEUILLE'!I15 -> 161.8 | J5: ='📈 PORTEFEUILLE'!L15 -> 13591.2 | K5: =IFERROR('📈 PORTEFEUILLE'!G15*'📈 PORTEFEUILLE'!H15,0) -> 10073.666 | L5: ='📈 PORTEFEUILLE'!N15 -> 3517.5336 | M5: ='📈 PORTEFEUILLE'!O15 -> 0.34918107 | N5: ='📈 PORTEFEUILLE'!P15 -> 0.15917323 | O5: 0.0092 | P5: 126.38371 | Q5: 10.531976 | R5: ='📈 PORTEFEUILLE'!Q15 -> ✅ Accumuler
A6: ='📈 PORTEFEUILLE'!B29 -> TD.TO | B6: ='📈 PORTEFEUILLE'!C29 -> TD Bank | C6: ='📈 PORTEFEUILLE'!D29 -> Action | D6: ='📈 PORTEFEUILLE'!E29 -> T3 | E6: ='📈 PORTEFEUILLE'!F29 -> TFSA | F6: ='📈 PORTEFEUILLE'!G29 -> 87 | G6: ='📈 PORTEFEUILLE'!I29 -> 128.05 | H6: ='📈 PORTEFEUILLE'!K29 -> CAD | I6: ='📈 PORTEFEUILLE'!I29 -> 128.05 | J6: ='📈 PORTEFEUILLE'!L29 -> 11140.35 | K6: =IFERROR('📈 PORTEFEUILLE'!G29*'📈 PORTEFEUILLE'!H29,0) -> 6945.6276 | L6: ='📈 PORTEFEUILLE'!N29 -> 4194.7224 | M6: ='📈 PORTEFEUILLE'!O29 -> 0.60393713 | N6: ='📈 PORTEFEUILLE'!P29 -> 0.13047012 | O6: 0.048 | P6: 544.17456 | Q6: 45.34788 | R6: ='📈 PORTEFEUILLE'!Q29 -> 🔵 Diluer — ne plus acheter
A7: ='📈 PORTEFEUILLE'!B19 -> SMH | B7: ='📈 PORTEFEUILLE'!C19 -> VanEck Semis | C7: ='📈 PORTEFEUILLE'!D19 -> ETF | D7: ='📈 PORTEFEUILLE'!E19 -> T1 | E7: ='📈 PORTEFEUILLE'!F19 -> TFSA | F7: ='📈 PORTEFEUILLE'!G19 -> 19.2266 | G7: ='📈 PORTEFEUILLE'!I19 -> 525.18075 | H7: ='📈 PORTEFEUILLE'!K19 -> USD | I7: ='📈 PORTEFEUILLE'!I19 -> 525.18075 | J7: ='📈 PORTEFEUILLE'!L19 -> 10097.44 | K7: =IFERROR('📈 PORTEFEUILLE'!G19*'📈 PORTEFEUILLE'!H19,0) -> 7566.9226 | L7: ='📈 PORTEFEUILLE'!N19 -> 2530.5176 | M7: ='📈 PORTEFEUILLE'!O19 -> 0.33441832 | N7: ='📈 PORTEFEUILLE'!P19 -> 0.11825609 | O7: 0.007 | P7: 72.596073 | Q7: 6.0496728 | R7: ='📈 PORTEFEUILLE'!Q19 -> ✅ Accumuler
A8: ='📈 PORTEFEUILLE'!B17 -> AVGO | B8: ='📈 PORTEFEUILLE'!C17 -> Broadcom | C8: ='📈 PORTEFEUILLE'!D17 -> Action | D8: ='📈 PORTEFEUILLE'!E17 -> T1 | E8: ='📈 PORTEFEUILLE'!F17 -> TFSA | F8: ='📈 PORTEFEUILLE'!G17 -> 16.5743 | G8: ='📈 PORTEFEUILLE'!I17 -> 436.81674 | H8: ='📈 PORTEFEUILLE'!K17 -> USD | I8: ='📈 PORTEFEUILLE'!I17 -> 436.81674 | J8: ='📈 PORTEFEUILLE'!L17 -> 7239.9318 | K8: =IFERROR('📈 PORTEFEUILLE'!G17*'📈 PORTEFEUILLE'!H17,0) -> 5671.0509 | L8: ='📈 PORTEFEUILLE'!N17 -> 1568.8809 | M8: ='📈 PORTEFEUILLE'!O17 -> 0.27664729 | N8: ='📈 PORTEFEUILLE'!P17 -> 0.084790404 | O8: 0.012 | P8: 91.446739 | Q8: 7.6205616 | R8: ='📈 PORTEFEUILLE'!Q17 -> ✅ Accumuler
A9: ='📈 PORTEFEUILLE'!B22 -> GEV | B9: ='📈 PORTEFEUILLE'!C22 -> GE Vernova | C9: ='📈 PORTEFEUILLE'!D22 -> Action | D9: ='📈 PORTEFEUILLE'!E22 -> T1 | E9: ='📈 PORTEFEUILLE'!F22 -> TFSA | F9: ='📈 PORTEFEUILLE'!G22 -> 2.4431 | G9: ='📈 PORTEFEUILLE'!I22 -> 1091.5266 | H9: ='📈 PORTEFEUILLE'!K22 -> USD | I9: ='📈 PORTEFEUILLE'!I22 -> 1091.5266 | J9: ='📈 PORTEFEUILLE'!L22 -> 2666.7087 | K9: =IFERROR('📈 PORTEFEUILLE'!G22*'📈 PORTEFEUILLE'!H22,0) -> 2032.6365 | L9: ='📈 PORTEFEUILLE'!N22 -> 634.0722 | M9: ='📈 PORTEFEUILLE'!O22 -> 0.3119457 | N9: ='📈 PORTEFEUILLE'!P22 -> 0.031231138 | O9: 0.003 | P9: 8.3536708 | Q9: 0.69613923 | R9: ='📈 PORTEFEUILLE'!Q22 -> ✅ Accumuler
A10: ='📈 PORTEFEUILLE'!B62 -> SCHD | B10: ='📈 PORTEFEUILLE'!C62 -> Schwab US Div | C10: ='📈 PORTEFEUILLE'!D62 -> ETF | D10: ='📈 PORTEFEUILLE'!E62 -> T1 | E10: ='📈 PORTEFEUILLE'!F62 -> REER | F10: ='📈 PORTEFEUILLE'!G62 -> 64.3053 | G10: ='📈 PORTEFEUILLE'!I62 -> 41.76172 | H10: ='📈 PORTEFEUILLE'!K62 -> USD | I10: ='📈 PORTEFEUILLE'!I62 -> 41.76172 | J10: ='📈 PORTEFEUILLE'!L62 -> 2685.4999 | K10: =IFERROR('📈 PORTEFEUILLE'!G62*'📈 PORTEFEUILLE'!H62,0) -> 1639.8366 | L10: ='📈 PORTEFEUILLE'!N62 -> 1045.6633 | M10: ='📈 PORTEFEUILLE'!O62 -> 0 | N10: ='📈 PORTEFEUILLE'!P62 -> 0 | O10: 0.035 | P10: 94.436704 | Q10: 7.8697254 | R10: ='📈 PORTEFEUILLE'!Q62 -> ✅ REER débloqué · accumuler $2,000/mois · snowball ARC +$1,060
A11: ='📈 PORTEFEUILLE'!B47 -> VFV.TO | B11: ='📈 PORTEFEUILLE'!C47 -> Vanguard S&P 500 | C11: ='📈 PORTEFEUILLE'!D47 -> ETF | D11: ='📈 PORTEFEUILLE'!E47 -> T1 | E11: ='📈 PORTEFEUILLE'!F47 -> FHSA | F11: ='📈 PORTEFEUILLE'!G47 -> 16 | G11: ='📈 PORTEFEUILLE'!I47 -> 161.8 | H11: ='📈 PORTEFEUILLE'!K47 -> CAD | I11: ='📈 PORTEFEUILLE'!I47 -> 161.8 | J11: ='📈 PORTEFEUILLE'!L47 -> 2588.8 | K11: =IFERROR('📈 PORTEFEUILLE'!G47*'📈 PORTEFEUILLE'!H47,0) -> 2518.0992 | L11: ='📈 PORTEFEUILLE'!N47 -> 70.7008 | M11: ='📈 PORTEFEUILLE'!O47 -> 0 | N11: ='📈 PORTEFEUILLE'!P47 -> 0 | O11: 0.0092 | P11: 24.073088 | Q11: 2.0060907 | R11: ='📈 PORTEFEUILLE'!Q47 -> ✅ Achat auto $2,500/mois
A12: ='📈 PORTEFEUILLE'!B16 -> GOOG | B12: ='📈 PORTEFEUILLE'!C16 -> Alphabet | C12: ='📈 PORTEFEUILLE'!D16 -> Action | D12: ='📈 PORTEFEUILLE'!E16 -> T1 | E12: ='📈 PORTEFEUILLE'!F16 -> TFSA | F12: ='📈 PORTEFEUILLE'!G16 -> 6 | G12: ='📈 PORTEFEUILLE'!I16 -> 408.74961 | H12: ='📈 PORTEFEUILLE'!K16 -> USD | I12: ='📈 PORTEFEUILLE'!I16 -> 408.74961 | J12: ='📈 PORTEFEUILLE'!L16 -> 2452.4977 | K12: =IFERROR('📈 PORTEFEUILLE'!G16*'📈 PORTEFEUILLE'!H16,0) -> 543.6354 | L12: ='📈 PORTEFEUILLE'!N16 -> 1908.8623 | M12: ='📈 PORTEFEUILLE'!O16 -> 3.5112914 | N12: ='📈 PORTEFEUILLE'!P16 -> 0.028722407 | O12: 0.005 | P12: 12.462868 | Q12: 1.0385724 | R12: ='📈 PORTEFEUILLE'!Q16 -> ✅ Accumuler
A13: ='📈 PORTEFEUILLE'!B30 -> ZLB.TO | B13: ='📈 PORTEFEUILLE'!C30 -> BMO Low Vol | C13: ='📈 PORTEFEUILLE'!D30 -> ETF | D13: ='📈 PORTEFEUILLE'!E30 -> T3 | E13: ='📈 PORTEFEUILLE'!F30 -> TFSA | F13: ='📈 PORTEFEUILLE'!G30 -> 37 | G13: ='📈 PORTEFEUILLE'!I30 -> 59.04 | H13: ='📈 PORTEFEUILLE'!K30 -> CAD | I13: ='📈 PORTEFEUILLE'!I30 -> 59.04 | J13: ='📈 PORTEFEUILLE'!L30 -> 2184.48 | K13: =IFERROR('📈 PORTEFEUILLE'!G30*'📈 PORTEFEUILLE'!H30,0) -> 2151.2392 | L13: ='📈 PORTEFEUILLE'!N30 -> 33.2408 | M13: ='📈 PORTEFEUILLE'!O30 -> 0.015451931 | N13: ='📈 PORTEFEUILLE'!P30 -> 0.02558352 | O13: 0.024 | P13: 52.40088 | Q13: 4.36674 | R13: ='📈 PORTEFEUILLE'!Q30 -> 🔵 Garder
A14: ='📈 PORTEFEUILLE'!B18 -> AMZN | B14: ='📈 PORTEFEUILLE'!C18 -> Amazon | C14: ='📈 PORTEFEUILLE'!D18 -> Action | D14: ='📈 PORTEFEUILLE'!E18 -> T1 | E14: ='📈 PORTEFEUILLE'!F18 -> TFSA | F14: ='📈 PORTEFEUILLE'!G18 -> 7.4817 | G14: ='📈 PORTEFEUILLE'!I18 -> 281.57975 | H14: ='📈 PORTEFEUILLE'!K18 -> USD | I14: ='📈 PORTEFEUILLE'!I18 -> 281.57975 | J14: ='📈 PORTEFEUILLE'!L18 -> 2106.6952 | K14: =IFERROR('📈 PORTEFEUILLE'!G18*'📈 PORTEFEUILLE'!H18,0) -> 850.95135 | L14: ='📈 PORTEFEUILLE'!N18 -> 1255.7439 | M14: ='📈 PORTEFEUILLE'!O18 -> 1.4756941 | N14: ='📈 PORTEFEUILLE'!P18 -> 0.024672545 | O14: 0 | P14: 0 | Q14: 0 | R14: ='📈 PORTEFEUILLE'!Q18 -> ✅ Accumuler
A15: ='📈 PORTEFEUILLE'!B48 -> AMZN | B15: ='📈 PORTEFEUILLE'!C48 -> Amazon | C15: ='📈 PORTEFEUILLE'!D48 -> Action | D15: ='📈 PORTEFEUILLE'!E48 -> T1 | E15: ='📈 PORTEFEUILLE'!F48 -> FHSA | F15: ='📈 PORTEFEUILLE'!G48 -> 7 | G15: ='📈 PORTEFEUILLE'!I48 -> 281.57975 | H15: ='📈 PORTEFEUILLE'!K48 -> USD | I15: ='📈 PORTEFEUILLE'!I48 -> 281.57975 | J15: ='📈 PORTEFEUILLE'!L48 -> 1971.0583 | K15: =IFERROR('📈 PORTEFEUILLE'!G48*'📈 PORTEFEUILLE'!H48,0) -> 1084.5926 | L15: ='📈 PORTEFEUILLE'!N48 -> 886.46567 | M15: ='📈 PORTEFEUILLE'!O48 -> 0.028077051 | N15: ='📈 PORTEFEUILLE'!P48 -> 0.030318711 | O15: 0 | P15: 0 | Q15: 0 | R15: ='📈 PORTEFEUILLE'!Q48 -> ✅ Garder
A16: ='📈 PORTEFEUILLE'!B51 -> TD.TO | B16: ='📈 PORTEFEUILLE'!C51 -> TD Bank | C16: ='📈 PORTEFEUILLE'!D51 -> Action | D16: ='📈 PORTEFEUILLE'!E51 -> T3 | E16: ='📈 PORTEFEUILLE'!F51 -> FHSA | F16: ='📈 PORTEFEUILLE'!G51 -> 15 | G16: ='📈 PORTEFEUILLE'!I51 -> 128.05 | H16: ='📈 PORTEFEUILLE'!K51 -> CAD | I16: ='📈 PORTEFEUILLE'!I51 -> 128.05 | J16: ='📈 PORTEFEUILLE'!L51 -> 1920.75 | K16: =IFERROR('📈 PORTEFEUILLE'!G51*'📈 PORTEFEUILLE'!H51,0) -> 1234.35 | L16: ='📈 PORTEFEUILLE'!N51 -> 686.4 | M16: ='📈 PORTEFEUILLE'!O51 -> -0.0052421368 | N16: ='📈 PORTEFEUILLE'!P51 -> 0.0070005444 | O16: 0.048 | P16: 93.8232 | Q16: 7.8186 | R16: ='📈 PORTEFEUILLE'!Q51 -> 🔵 Garder
A17: ='📈 PORTEFEUILLE'!B37 -> XEI.TO | B17: ='📈 PORTEFEUILLE'!C37 -> iShares High Div | C17: ='📈 PORTEFEUILLE'!D37 -> ETF | D17: ='📈 PORTEFEUILLE'!E37 -> T4 | E17: ='📈 PORTEFEUILLE'!F37 -> TFSA | F17: ='📈 PORTEFEUILLE'!G37 -> 51 | G17: ='📈 PORTEFEUILLE'!I37 -> 35.89 | H17: ='📈 PORTEFEUILLE'!K37 -> CAD | I17: ='📈 PORTEFEUILLE'!I37 -> 35.89 | J17: ='📈 PORTEFEUILLE'!L37 -> 1830.39 | K17: =IFERROR('📈 PORTEFEUILLE'!G37*'📈 PORTEFEUILLE'!H37,0) -> 1564.7361 | L17: ='📈 PORTEFEUILLE'!N37 -> 265.6539 | M17: ='📈 PORTEFEUILLE'!O37 -> 0.16977553 | N17: ='📈 PORTEFEUILLE'!P37 -> 0.021436598 | O17: 0.055 | P17: 100.1385 | Q17: 8.344875 | R17: ='📈 PORTEFEUILLE'!Q37 -> 🔄 Diluer
A18: ='📈 PORTEFEUILLE'!B49 -> QQQM | B18: ='📈 PORTEFEUILLE'!C49 -> Invesco Nasdaq100 | C18: ='📈 PORTEFEUILLE'!D49 -> ETF | D18: ='📈 PORTEFEUILLE'!E49 -> T2 | E18: ='📈 PORTEFEUILLE'!F49 -> FHSA | F18: ='📈 PORTEFEUILLE'!G49 -> 5.311 | G18: ='📈 PORTEFEUILLE'!I49 -> 331.44975 | H18: ='📈 PORTEFEUILLE'!K49 -> USD | I18: ='📈 PORTEFEUILLE'!I49 -> 331.44975 | J18: ='📈 PORTEFEUILLE'!L49 -> 1760.3296 | K18: =IFERROR('📈 PORTEFEUILLE'!G49*'📈 PORTEFEUILLE'!H49,0) -> 1313.9754 | L18: ='📈 PORTEFEUILLE'!N49 -> 446.35426 | M18: ='📈 PORTEFEUILLE'!O49 -> 0.81732594 | N18: ='📈 PORTEFEUILLE'!P49 -> 0.023084033 | O18: 0.006 | P18: 10.750288 | Q18: 0.89585737 | R18: ='📈 PORTEFEUILLE'!Q49 -> ✅ Migration ZQQ ✅
A19: ='📈 PORTEFEUILLE'!B54 -> SRU.UN.TO | B19: ='📈 PORTEFEUILLE'!C54 -> SmartCentres | C19: ='📈 PORTEFEUILLE'!D54 -> REIT | D19: ='📈 PORTEFEUILLE'!E54 -> T4 | E19: ='📈 PORTEFEUILLE'!F54 -> FHSA | F19: ='📈 PORTEFEUILLE'!G54 -> 63 | G19: ='📈 PORTEFEUILLE'!I54 -> 26.84 | H19: ='📈 PORTEFEUILLE'!K54 -> CAD | I19: ='📈 PORTEFEUILLE'!I54 -> 26.84 | J19: ='📈 PORTEFEUILLE'!L54 -> 1690.92 | K19: =IFERROR('📈 PORTEFEUILLE'!G54*'📈 PORTEFEUILLE'!H54,0) -> 1487.43 | L19: ='📈 PORTEFEUILLE'!N54 -> 203.49 | M19: ='📈 PORTEFEUILLE'!O54 -> -0.00045033911 | N19: ='📈 PORTEFEUILLE'!P54 -> 0.0020743395 | O19: 0.072 | P19: 121.338 | Q19: 10.1115 | R19: ='📈 PORTEFEUILLE'!Q54 -> 🔄 Diluer
A20: ='📈 PORTEFEUILLE'!B55 -> REI.UN.TO | B20: ='📈 PORTEFEUILLE'!C55 -> RioCan REIT | C20: ='📈 PORTEFEUILLE'!D55 -> REIT | D20: ='📈 PORTEFEUILLE'!E55 -> T4 | E20: ='📈 PORTEFEUILLE'!F55 -> FHSA | F20: ='📈 PORTEFEUILLE'!G55 -> 80 | G20: ='📈 PORTEFEUILLE'!I55 -> 19.02 | H20: ='📈 PORTEFEUILLE'!K55 -> CAD | I20: ='📈 PORTEFEUILLE'!I55 -> 19.02 | J20: ='📈 PORTEFEUILLE'!L55 -> 1521.6 | K20: =IFERROR('📈 PORTEFEUILLE'!G55*'📈 PORTEFEUILLE'!H55,0) -> 1498.4 | L20: ='📈 PORTEFEUILLE'!N55 -> 23.2 | M20: ='📈 PORTEFEUILLE'!O55 -> 0.13680644 | N20: ='📈 PORTEFEUILLE'!P55 -> 0.019803196 | O20: 0.056 | P20: 85.5232 | Q20: 7.1269333 | R20: ='📈 PORTEFEUILLE'!Q55 -> 🔄 Diluer
A21: ='📈 PORTEFEUILLE'!B38 -> SRU.UN.TO | B21: ='📈 PORTEFEUILLE'!C38 -> SmartCentres | C21: ='📈 PORTEFEUILLE'!D38 -> REIT | D21: ='📈 PORTEFEUILLE'!E38 -> T4 | E21: ='📈 PORTEFEUILLE'!F38 -> TFSA | F21: ='📈 PORTEFEUILLE'!G38 -> 57 | G21: ='📈 PORTEFEUILLE'!I38 -> 26.84 | H21: ='📈 PORTEFEUILLE'!K38 -> CAD | I21: ='📈 PORTEFEUILLE'!I38 -> 26.84 | J21: ='📈 PORTEFEUILLE'!L38 -> 1529.88 | K21: =IFERROR('📈 PORTEFEUILLE'!G38*'📈 PORTEFEUILLE'!H38,0) -> 1439.4951 | L21: ='📈 PORTEFEUILLE'!N38 -> 90.3849 | M21: ='📈 PORTEFEUILLE'!O38 -> 0.062789307 | N21: ='📈 PORTEFEUILLE'!P38 -> 0.017917178 | O21: 0.072 | P21: 109.782 | Q21: 9.1485 | R21: ='📈 PORTEFEUILLE'!Q38 -> 🔄 Diluer
A22: ='📈 PORTEFEUILLE'!B26 -> QQQM | B22: ='📈 PORTEFEUILLE'!C26 -> Invesco Nasdaq100 | C22: ='📈 PORTEFEUILLE'!D26 -> ETF | D22: ='📈 PORTEFEUILLE'!E26 -> T2 | E22: ='📈 PORTEFEUILLE'!F26 -> TFSA | F22: ='📈 PORTEFEUILLE'!G26 -> 4.4515 | G22: ='📈 PORTEFEUILLE'!I26 -> 331.44975 | H22: ='📈 PORTEFEUILLE'!K26 -> USD | I22: ='📈 PORTEFEUILLE'!I26 -> 331.44975 | J22: ='📈 PORTEFEUILLE'!L26 -> 1475.4486 | K22: =IFERROR('📈 PORTEFEUILLE'!G26*'📈 PORTEFEUILLE'!H26,0) -> 1099.9959 | L22: ='📈 PORTEFEUILLE'!N26 -> 375.45266 | M22: ='📈 PORTEFEUILLE'!O26 -> 0.34132187 | N22: ='📈 PORTEFEUILLE'!P26 -> 0.017279704 | O22: 0.006 | P22: 9.010527 | Q22: 0.75087725 | R22: ='📈 PORTEFEUILLE'!Q26 -> ✅ Migration ZQQ ✅
A23: ='📈 PORTEFEUILLE'!B31 -> H.TO | B23: ='📈 PORTEFEUILLE'!C31 -> Hydro One | C23: ='📈 PORTEFEUILLE'!D31 -> Action | D23: ='📈 PORTEFEUILLE'!E31 -> T3 | E23: ='📈 PORTEFEUILLE'!F31 -> TFSA | F23: ='📈 PORTEFEUILLE'!G31 -> 22 | G23: ='📈 PORTEFEUILLE'!I31 -> 60.09 | H23: ='📈 PORTEFEUILLE'!K31 -> CAD | I23: ='📈 PORTEFEUILLE'!I31 -> 60.09 | J23: ='📈 PORTEFEUILLE'!L31 -> 1321.98 | K23: =IFERROR('📈 PORTEFEUILLE'!G31*'📈 PORTEFEUILLE'!H31,0) -> 1163.0586 | L23: ='📈 PORTEFEUILLE'!N31 -> 158.9214 | M23: ='📈 PORTEFEUILLE'!O31 -> 0.13664092 | N23: ='📈 PORTEFEUILLE'!P31 -> 0.015482358 | O23: 0.03 | P23: 38.7222 | Q23: 3.22685 | R23: ='📈 PORTEFEUILLE'!Q31 -> 🔵 Garder
A24: ='📈 PORTEFEUILLE'!B39 -> XIC.TO | B24: ='📈 PORTEFEUILLE'!C39 -> iShares TSX | C24: ='📈 PORTEFEUILLE'!D39 -> ETF | D24: ='📈 PORTEFEUILLE'!E39 -> T4 | E24: ='📈 PORTEFEUILLE'!F39 -> TFSA | F24: ='📈 PORTEFEUILLE'!G39 -> 21 | G24: ='📈 PORTEFEUILLE'!I39 -> 52.08 | H24: ='📈 PORTEFEUILLE'!K39 -> CAD | I24: ='📈 PORTEFEUILLE'!I39 -> 52.08 | J24: ='📈 PORTEFEUILLE'!L39 -> 1093.68 | K24: =IFERROR('📈 PORTEFEUILLE'!G39*'📈 PORTEFEUILLE'!H39,0) -> 848.5386 | L24: ='📈 PORTEFEUILLE'!N39 -> 245.1414 | M24: ='📈 PORTEFEUILLE'!O39 -> 0.28889835 | N24: ='📈 PORTEFEUILLE'!P39 -> 0.012808625 | O24: 0.025 | P24: 27.8355 | Q24: 2.319625 | R24: ='📈 PORTEFEUILLE'!Q39 -> 🔄 Diluer
A25: ='📈 PORTEFEUILLE'!B23 -> MSFT | B25: ='📈 PORTEFEUILLE'!C23 -> Microsoft | C25: ='📈 PORTEFEUILLE'!D23 -> Action | D25: ='📈 PORTEFEUILLE'!E23 -> T2 | E25: ='📈 PORTEFEUILLE'!F23 -> TFSA | F25: ='📈 PORTEFEUILLE'!G23 -> 2 | G25: ='📈 PORTEFEUILLE'!I23 -> 536.32624 | H25: ='📈 PORTEFEUILLE'!K23 -> USD | I25: ='📈 PORTEFEUILLE'!I23 -> 536.32624 | J25: ='📈 PORTEFEUILLE'!L23 -> 1072.6525 | K25: =IFERROR('📈 PORTEFEUILLE'!G23*'📈 PORTEFEUILLE'!H23,0) -> 625.1876 | L25: ='📈 PORTEFEUILLE'!N23 -> 447.46489 | M25: ='📈 PORTEFEUILLE'!O23 -> 0.71572899 | N25: ='📈 PORTEFEUILLE'!P23 -> 0.012562361 | O25: 0.008 | P25: 8.7516451 | Q25: 0.72930375 | R25: ='📈 PORTEFEUILLE'!Q23 -> ✅ Garder
A26: ='📈 PORTEFEUILLE'!B25 -> TSLA | B26: ='📈 PORTEFEUILLE'!C25 -> Tesla | C26: ='📈 PORTEFEUILLE'!D25 -> Action | D26: ='📈 PORTEFEUILLE'!E25 -> T2 | E26: ='📈 PORTEFEUILLE'!F25 -> TFSA | F26: ='📈 PORTEFEUILLE'!G25 -> 1.8645 | G26: ='📈 PORTEFEUILLE'!I25 -> 530.42808 | H26: ='📈 PORTEFEUILLE'!K25 -> USD | I26: ='📈 PORTEFEUILLE'!I25 -> 530.42808 | J26: ='📈 PORTEFEUILLE'!L25 -> 988.98316 | K26: =IFERROR('📈 PORTEFEUILLE'!G25*'📈 PORTEFEUILLE'!H25,0) -> 565.99582 | L26: ='📈 PORTEFEUILLE'!N25 -> 422.98733 | M26: ='📈 PORTEFEUILLE'!O25 -> 0.74733295 | N26: ='📈 PORTEFEUILLE'!P25 -> 0.011582468 | O26: 0 | P26: 0 | Q26: 0 | R26: ='📈 PORTEFEUILLE'!Q25 -> ✅ Garder
A27: ='📈 PORTEFEUILLE'!B27 -> XEQT.TO | B27: ='📈 PORTEFEUILLE'!C27 -> iShares Core Eq | C27: ='📈 PORTEFEUILLE'!D27 -> ETF | D27: ='📈 PORTEFEUILLE'!E27 -> T2 | E27: ='📈 PORTEFEUILLE'!F27 -> TFSA | F27: ='📈 PORTEFEUILLE'!G27 -> 25 | G27: ='📈 PORTEFEUILLE'!I27 -> 39.85 | H27: ='📈 PORTEFEUILLE'!K27 -> CAD | I27: ='📈 PORTEFEUILLE'!I27 -> 39.85 | J27: ='📈 PORTEFEUILLE'!L27 -> 996.25 | K27: =IFERROR('📈 PORTEFEUILLE'!G27*'📈 PORTEFEUILLE'!H27,0) -> 999.25 | L27: ='📈 PORTEFEUILLE'!N27 -> -3 | M27: ='📈 PORTEFEUILLE'!O27 -> -0.0030022517 | N27: ='📈 PORTEFEUILLE'!P27 -> 0.011667574 | O27: 0.02 | P27: 20.23 | Q27: 1.6858333 | R27: ='📈 PORTEFEUILLE'!Q27 -> ✅ Migration ZEQT ✅
A28: ='📈 PORTEFEUILLE'!B56 -> XIC.TO | B28: ='📈 PORTEFEUILLE'!C56 -> iShares TSX | C28: ='📈 PORTEFEUILLE'!D56 -> ETF | D28: ='📈 PORTEFEUILLE'!E56 -> T4 | E28: ='📈 PORTEFEUILLE'!F56 -> FHSA | F28: ='📈 PORTEFEUILLE'!G56 -> 19 | G28: ='📈 PORTEFEUILLE'!I56 -> 52.08 | H28: ='📈 PORTEFEUILLE'!K56 -> CAD | I28: ='📈 PORTEFEUILLE'!I56 -> 52.08 | J28: ='📈 PORTEFEUILLE'!L56 -> 989.52 | K28: =IFERROR('📈 PORTEFEUILLE'!G56*'📈 PORTEFEUILLE'!H56,0) -> 919.0395 | L28: ='📈 PORTEFEUILLE'!N56 -> 70.4805 | M28: ='📈 PORTEFEUILLE'!O56 -> 0.015483182 | N28: ='📈 PORTEFEUILLE'!P56 -> 0.017820206 | O28: 0.025 | P28: 25.1845 | Q28: 2.0987083 | R28: ='📈 PORTEFEUILLE'!Q56 -> 🔄 Diluer
A29: ='📈 PORTEFEUILLE'!B24 -> NVDA | B29: ='📈 PORTEFEUILLE'!C24 -> NVIDIA | C29: ='📈 PORTEFEUILLE'!D24 -> Action | D29: ='📈 PORTEFEUILLE'!E24 -> T2 | E29: ='📈 PORTEFEUILLE'!F24 -> TFSA | F29: ='📈 PORTEFEUILLE'!G24 -> 4 | G29: ='📈 PORTEFEUILLE'!I24 -> 244.40097 | H29: ='📈 PORTEFEUILLE'!K24 -> USD | I29: ='📈 PORTEFEUILLE'!I24 -> 244.40097 | J29: ='📈 PORTEFEUILLE'!L24 -> 977.6039 | K29: =IFERROR('📈 PORTEFEUILLE'!G24*'📈 PORTEFEUILLE'!H24,0) -> 514.36 | L29: ='📈 PORTEFEUILLE'!N24 -> 463.2439 | M29: ='📈 PORTEFEUILLE'!O24 -> 0.90062194 | N29: ='📈 PORTEFEUILLE'!P24 -> 0.0114492 | O29: 0.003 | P29: 3.006365 | Q29: 0.25053042 | R29: ='📈 PORTEFEUILLE'!Q24 -> ✅ Garder
A30: ='📈 PORTEFEUILLE'!B57 -> XEI.TO | B30: ='📈 PORTEFEUILLE'!C57 -> iShares High Div | C30: ='📈 PORTEFEUILLE'!D57 -> ETF | D30: ='📈 PORTEFEUILLE'!E57 -> T4 | E30: ='📈 PORTEFEUILLE'!F57 -> FHSA | F30: ='📈 PORTEFEUILLE'!G57 -> 26 | G30: ='📈 PORTEFEUILLE'!I57 -> 35.89 | H30: ='📈 PORTEFEUILLE'!K57 -> CAD | I30: ='📈 PORTEFEUILLE'!I57 -> 35.89 | J30: ='📈 PORTEFEUILLE'!L57 -> 933.14 | K30: =IFERROR('📈 PORTEFEUILLE'!G57*'📈 PORTEFEUILLE'!H57,0) -> 847.8886 | L30: ='📈 PORTEFEUILLE'!N57 -> 85.2514 | M30: ='📈 PORTEFEUILLE'!O57 -> 0.076689304 | N30: ='📈 PORTEFEUILLE'!P57 -> 0.011588756 | O30: 0.055 | P30: 51.051 | Q30: 4.25425 | R30: ='📈 PORTEFEUILLE'!Q57 -> 🔄 Migration VDY ✅
A31: ='📈 PORTEFEUILLE'!B20 -> META | B31: ='📈 PORTEFEUILLE'!C20 -> Meta Platforms | C31: ='📈 PORTEFEUILLE'!D20 -> Action | D31: ='📈 PORTEFEUILLE'!E20 -> T1 | E31: ='📈 PORTEFEUILLE'!F20 -> TFSA | F31: ='📈 PORTEFEUILLE'!G20 -> 1 | G31: ='📈 PORTEFEUILLE'!I20 -> 832.12939 | H31: ='📈 PORTEFEUILLE'!K20 -> USD | I31: ='📈 PORTEFEUILLE'!I20 -> 832.12939 | J31: ='📈 PORTEFEUILLE'!L20 -> 832.12939 | K31: =IFERROR('📈 PORTEFEUILLE'!G20*'📈 PORTEFEUILLE'!H20,0) -> 637.7698 | L31: ='📈 PORTEFEUILLE'!N20 -> 194.35959 | M31: ='📈 PORTEFEUILLE'!O20 -> 0.30474881 | N31: ='📈 PORTEFEUILLE'!P20 -> 0.0097454768 | O31: 0.004 | P31: 3.5335398 | Q31: 0.29446165 | R31: ='📈 PORTEFEUILLE'!Q20 -> ✅ Accumuler
A32: ='📈 PORTEFEUILLE'!B33 -> QTUM | B32: ='📈 PORTEFEUILLE'!C33 -> Defiance Quantum | C32: ='📈 PORTEFEUILLE'!D33 -> ETF | D32: ='📈 PORTEFEUILLE'!E33 -> T3 | E32: ='📈 PORTEFEUILLE'!F33 -> TFSA | F32: ='📈 PORTEFEUILLE'!G33 -> 5 | G32: ='📈 PORTEFEUILLE'!I33 -> 148.29478 | H32: ='📈 PORTEFEUILLE'!K33 -> USD | I32: ='📈 PORTEFEUILLE'!I33 -> 148.29478 | J32: ='📈 PORTEFEUILLE'!L33 -> 741.47392 | K32: =IFERROR('📈 PORTEFEUILLE'!G33*'📈 PORTEFEUILLE'!H33,0) -> 604.05 | L32: ='📈 PORTEFEUILLE'!N33 -> 137.42391 | M32: ='📈 PORTEFEUILLE'!O33 -> 0.2275042 | N32: ='📈 PORTEFEUILLE'!P33 -> 0.0086837659 | O32: 0.004 | P32: 3.0591369 | Q32: 0.25492808 | R32: ='📈 PORTEFEUILLE'!Q33 -> 🔵 Garder (max 5)
A33: ='📈 PORTEFEUILLE'!B21 -> ENB.TO | B33: ='📈 PORTEFEUILLE'!C21 -> Enbridge | C33: ='📈 PORTEFEUILLE'!D21 -> Action | D33: ='📈 PORTEFEUILLE'!E21 -> T1 | E33: ='📈 PORTEFEUILLE'!F21 -> TFSA | F33: ='📈 PORTEFEUILLE'!G21 -> 9 | G33: ='📈 PORTEFEUILLE'!I21 -> 74.28 | H33: ='📈 PORTEFEUILLE'!K21 -> CAD | I33: ='📈 PORTEFEUILLE'!I21 -> 74.28 | J33: ='📈 PORTEFEUILLE'!L21 -> 668.52 | K33: =IFERROR('📈 PORTEFEUILLE'!G21*'📈 PORTEFEUILLE'!H21,0) -> 446.58 | L33: ='📈 PORTEFEUILLE'!N21 -> 221.94 | M33: ='📈 PORTEFEUILLE'!O21 -> 0.49697703 | N33: ='📈 PORTEFEUILLE'!P21 -> 0.0078293667 | O33: 0.065 | P33: 42.6231 | Q33: 3.551925 | R33: ='📈 PORTEFEUILLE'!Q21 -> ✅ Garder
A34: ='📈 PORTEFEUILLE'!B50 -> XEQT.TO | B34: ='📈 PORTEFEUILLE'!C50 -> iShares Core Eq | C34: ='📈 PORTEFEUILLE'!D50 -> ETF | D34: ='📈 PORTEFEUILLE'!E50 -> T2 | E34: ='📈 PORTEFEUILLE'!F50 -> FHSA | F34: ='📈 PORTEFEUILLE'!G50 -> 15 | G34: ='📈 PORTEFEUILLE'!I50 -> 39.85 | H34: ='📈 PORTEFEUILLE'!K50 -> CAD | I34: ='📈 PORTEFEUILLE'!I50 -> 39.85 | J34: ='📈 PORTEFEUILLE'!L50 -> 597.75 | K34: =IFERROR('📈 PORTEFEUILLE'!G50*'📈 PORTEFEUILLE'!H50,0) -> 600.9 | L34: ='📈 PORTEFEUILLE'!N50 -> -3.15 | M34: ='📈 PORTEFEUILLE'!O50 -> 0.33969758 | N34: ='📈 PORTEFEUILLE'!P50 -> 0.020616087 | O34: 0.02 | P34: 12.138 | Q34: 1.0115 | R34: ='📈 PORTEFEUILLE'!Q50 -> ✅ Migration ZEQT ✅
A35: ='📈 PORTEFEUILLE'!B52 -> H.TO | B35: ='📈 PORTEFEUILLE'!C52 -> Hydro One | C35: ='📈 PORTEFEUILLE'!D52 -> Action | D35: ='📈 PORTEFEUILLE'!E52 -> T3 | E35: ='📈 PORTEFEUILLE'!F52 -> FHSA | F35: ='📈 PORTEFEUILLE'!G52 -> 10 | G35: ='📈 PORTEFEUILLE'!I52 -> 60.09 | H35: ='📈 PORTEFEUILLE'!K52 -> CAD | I35: ='📈 PORTEFEUILLE'!I52 -> 60.09 | J35: ='📈 PORTEFEUILLE'!L52 -> 600.9 | K35: =IFERROR('📈 PORTEFEUILLE'!G52*'📈 PORTEFEUILLE'!H52,0) -> 517.8 | L35: ='📈 PORTEFEUILLE'!N52 -> 83.1 | M35: ='📈 PORTEFEUILLE'!O52 -> 0.55608215 | N35: ='📈 PORTEFEUILLE'!P52 -> 0.022494849 | O35: 0.03 | P35: 17.601 | Q35: 1.46675 | R35: ='📈 PORTEFEUILLE'!Q52 -> 🔵 Garder
A36: ='📈 PORTEFEUILLE'!B28 -> SPGI | B36: ='📈 PORTEFEUILLE'!C28 -> S&P Global | C36: ='📈 PORTEFEUILLE'!D28 -> Action | D36: ='📈 PORTEFEUILLE'!E28 -> T2 | E36: ='📈 PORTEFEUILLE'!F28 -> TFSA | F36: ='📈 PORTEFEUILLE'!G28 -> 0.9996 | G36: ='📈 PORTEFEUILLE'!I28 -> 572.85419 | H36: ='📈 PORTEFEUILLE'!K28 -> USD | I36: ='📈 PORTEFEUILLE'!I28 -> 572.85419 | J36: ='📈 PORTEFEUILLE'!L28 -> 572.62505 | K36: =IFERROR('📈 PORTEFEUILLE'!G28*'📈 PORTEFEUILLE'!H28,0) -> 443.0685 | L36: ='📈 PORTEFEUILLE'!N28 -> 129.55655 | M36: ='📈 PORTEFEUILLE'!O28 -> 0.29240749 | N36: ='📈 PORTEFEUILLE'!P28 -> 0.0067062938 | O36: 0.009 | P36: 5.2158413 | Q36: 0.43465344 | R36: ='📈 PORTEFEUILLE'!Q28 -> ✅ Garder
A37: ='📈 PORTEFEUILLE'!B32 -> T.TO | B37: ='📈 PORTEFEUILLE'!C32 -> TELUS | C37: ='📈 PORTEFEUILLE'!D32 -> Action | D37: ='📈 PORTEFEUILLE'!E32 -> T3 | E37: ='📈 PORTEFEUILLE'!F32 -> TFSA | F37: ='📈 PORTEFEUILLE'!G32 -> 32 | G37: ='📈 PORTEFEUILLE'!I32 -> 18.01 | H37: ='📈 PORTEFEUILLE'!K32 -> CAD | I37: ='📈 PORTEFEUILLE'!I32 -> 18.01 | J37: ='📈 PORTEFEUILLE'!L32 -> 576.32 | K37: =IFERROR('📈 PORTEFEUILLE'!G32*'📈 PORTEFEUILLE'!H32,0) -> 705.28 | L37: ='📈 PORTEFEUILLE'!N32 -> -128.96 | M37: ='📈 PORTEFEUILLE'!O32 -> -0.18284936 | N37: ='📈 PORTEFEUILLE'!P32 -> 0.0067495672 | O37: 0.085 | P37: 49.0688 | Q37: 4.0890667 | R37: ='📈 PORTEFEUILLE'!Q32 -> 👀 Surveiller div Q3
A38: ='📈 PORTEFEUILLE'!B40 -> ZRE.TO | B38: ='📈 PORTEFEUILLE'!C40 -> BMO Equal REITs | C38: ='📈 PORTEFEUILLE'!D40 -> ETF | D38: ='📈 PORTEFEUILLE'!E40 -> T4 | E38: ='📈 PORTEFEUILLE'!F40 -> TFSA | F38: ='📈 PORTEFEUILLE'!G40 -> 19 | G38: ='📈 PORTEFEUILLE'!I40 -> 22.33 | H38: ='📈 PORTEFEUILLE'!K40 -> CAD | I38: ='📈 PORTEFEUILLE'!I40 -> 22.33 | J38: ='📈 PORTEFEUILLE'!L40 -> 424.27 | K38: =IFERROR('📈 PORTEFEUILLE'!G40*'📈 PORTEFEUILLE'!H40,0) -> 395.77 | L38: ='📈 PORTEFEUILLE'!N40 -> 28.5 | M38: ='📈 PORTEFEUILLE'!O40 -> 0.072011522 | N38: ='📈 PORTEFEUILLE'!P40 -> 0.0049688348 | O38: 0.05 | P38: 21.4225 | Q38: 1.7852083 | R38: ='📈 PORTEFEUILLE'!Q40 -> 🔄 Diluer
A39: ='📈 PORTEFEUILLE'!B41 -> MFC.TO | B39: ='📈 PORTEFEUILLE'!C41 -> Manulife | C39: ='📈 PORTEFEUILLE'!D41 -> Action | D39: ='📈 PORTEFEUILLE'!E41 -> T4 | E39: ='📈 PORTEFEUILLE'!F41 -> TFSA | F39: ='📈 PORTEFEUILLE'!G41 -> 8 | G39: ='📈 PORTEFEUILLE'!I41 -> 45.9 | H39: ='📈 PORTEFEUILLE'!K41 -> CAD | I39: ='📈 PORTEFEUILLE'!I41 -> 45.9 | J39: ='📈 PORTEFEUILLE'!L41 -> 367.2 | K39: =IFERROR('📈 PORTEFEUILLE'!G41*'📈 PORTEFEUILLE'!H41,0) -> 413.6 | L39: ='📈 PORTEFEUILLE'!N41 -> -46.4 | M39: ='📈 PORTEFEUILLE'!O41 -> -0.11218569 | N39: ='📈 PORTEFEUILLE'!P41 -> 0.0043004599 | O39: 0.044 | P39: 16.14624 | Q39: 1.34552 | R39: ='📈 PORTEFEUILLE'!Q41 -> 🔄 Diluer
A40: ='📈 PORTEFEUILLE'!B34 -> HURA.TO | B40: ='📈 PORTEFEUILLE'!C34 -> Global X Uranium | C40: ='📈 PORTEFEUILLE'!D34 -> ETF | D40: ='📈 PORTEFEUILLE'!E34 -> T3 | E40: ='📈 PORTEFEUILLE'!F34 -> TFSA | F40: ='📈 PORTEFEUILLE'!G34 -> 6 | G40: ='📈 PORTEFEUILLE'!I34 -> 57.54 | H40: ='📈 PORTEFEUILLE'!K34 -> CAD | I40: ='📈 PORTEFEUILLE'!I34 -> 57.54 | J40: ='📈 PORTEFEUILLE'!L34 -> 345.24 | K40: =IFERROR('📈 PORTEFEUILLE'!G34*'📈 PORTEFEUILLE'!H34,0) -> 331.5 | L40: ='📈 PORTEFEUILLE'!N34 -> 13.74 | M40: ='📈 PORTEFEUILLE'!O34 -> 0.041447964 | N40: ='📈 PORTEFEUILLE'!P34 -> 0.0040432755 | O40: 0.002 | P40: 0.71424 | Q40: 0.05952 | R40: ='📈 PORTEFEUILLE'!Q34 -> 🔵 Garder
...

Sheet 🏠 DASHBOARD
B1: 🏠 TABLEAU DE BORD · PORTEFEUILLE FI · MAXIMIZE — PAS DE CIBLE, TOUJOURS PLUS
B2: v49-S19 · 12 mars 2026 · Partenaire FI permanent : Claude · Plan $5,000/mois structuré
B4: ① STATUT SESSION · Cocher avant de commencer
B5: VÉRIFICATION | C5: VALEUR / STATUT | E5: CONTEXTE MARCHÉ | G5: INTENTION SESSION
B6: 📎 Wallet uploadé? | C6: ⬜ Confirmer | E6: =IFERROR("S&P "&TEXT(CONFIG!G36,"#,##0")&" ("&TEXT(CONFIG!B49,"+0.0%")&")","S&P: N/A") -> S&P 6,632 (-+4.3%) | G6: ⬜ Dire à Claude
B7: 📋 Questrade dump? | C7: ⬜ Confirmer | E7: =IFERROR("TSX "&TEXT(CONFIG!G37,"#,##0")&" ("&TEXT(CONFIG!B50,"+0.0%")&")","TSX: N/A") -> TSX 32,542 (+2.6%) | G7: BdC 18 mars · Fed 18-19 mars
B8: 💱 USD/CAD | C8: =CONFIG!B3 -> 1.3559 | E8: =IFERROR("USD/CAD "&TEXT(CONFIG!B3,"0.0000"),"N/A") -> USD/CAD 1.3559 | G8: =IFERROR(TEXT(NOW(),"dd mmm yyyy HH:MM")&" HNE","--") -> 15 Mar 2026 01:10 HNE
B9: 💰 Cash TFSA / FHSA | C9: =CONFIG!B37 -> 230.66 | E9: =CONFIG!B38 -> 15.13 | G9: VIX: saisir ⬜
B11: ② PORTFOLIO LIVE · Valeurs en temps réel depuis 📈 PORTEFEUILLE
B12: COMPTE | C12: VALEUR ACTUELLE | D12: DÉPOSÉ | E12: P&L $ | F12: P&L % | G12: ROOM DISPO | H12: NOTE / RÔLE
B13: TFSA 📈 | C13: ='📈 PORTEFEUILLE'!L44 -> 67855.03 | D13: ='📈 PORTEFEUILLE'!M44 -> 50044.273 | E13: ='📈 PORTEFEUILLE'!N44 -> 18727.904 | F13: ='📈 PORTEFEUILLE'!O44 -> 0 | G13: =CONFIG!B6 -> 69600 | H13: Croissance LT · Retraite · Intouchable
B14: FHSA 🏠 | C14: ='📈 PORTEFEUILLE'!L59 -> 14767.018 | D14: ='📈 PORTEFEUILLE'!M59 -> 10890.934 | E14: ='📈 PORTEFEUILLE'!N59 -> 2552.2128 | F14: ='📈 PORTEFEUILLE'!O59 -> 0.17283197 | G14: =CONFIG!B7 -> 13700 | H14: Maison 2030+ · Double exonération fiscale
B15: REER ❄️🔥 | C15: ='📈 PORTEFEUILLE'!L68 -> 2764.1683 | D15: ='📈 PORTEFEUILLE'!M68 -> 2095.7125 | E15: ='📈 PORTEFEUILLE'!N68 -> 1091.44 | F15: ='📈 PORTEFEUILLE'!O68 -> 0.39485295 | G15: =CONFIG!B8 -> 37008 | H15: RAP $60K · Snowball ARC $1,060/mois
B16: ▼ TOTAL PORTFOLIO | C16: ='📈 PORTEFEUILLE'!L70 -> 85386.216 | D16: ='📈 PORTEFEUILLE'!M70 -> 63030.92 | E16: ='📈 PORTEFEUILLE'!N70 -> 22371.557 | F16: ='📈 PORTEFEUILLE'!O70 -> 0.26200431 | G16: SNOWBALL: $1,590/mois | H16: Dividendes est. ~$3,200/an
B18: ③ ACTIONS URGENTES · Statut auto
B19: # | C19: ACTION | F19: STATUT | G19: IMPACT | H19: DÉLAI / NOTE
B20: 🔴 1 | C20: Ouvrir EQ Bank — Fonds urgence $15,000 | F20: =IF(CONFIG!B25>=15000,"✅ FAIT",IF(CONFIG!B25>0,"🟡 EN COURS","🔴 À FAIRE")) -> 🔴 À FAIRE | G20: Risque ×0 | H20: CE MOIS · Risque opérationnel #1
B21: 🔴 2 | C21: Vendre ZRE.TO + XIC.TO + VDU.TO → T1 (~$1,878) | F21: =IF(SUMIF('📈 PORTEFEUILLE'!B14:B64,"ZRE.TO",'📈 PORTEFEUILLE'!G14:G64)=0,"✅ FAIT","🔴 POST-BdC 18 mars") -> 🔴 POST-BdC 18 mars | G21: ~+$80/an | H21: Post-BdC 18 mars · T4→T1
B22: 🟡 3 | C22: Vérifier Mon Dossier ARC — Revenu net 2025 | F22: 🟡 PLANIFIER | G22: $1,500 crédit | H22: Avant déc 2026 · NON ÉLIG. 2026 ($140K > $129,590)
B23: ✅ 4 | C23: PLZ.UN 961u vendus @ $4.26 → AVGO+GEV+SMH | F23: ✅ EXÉCUTÉ 11 mars | G23: +$4,094 CAD | H23: T4→T1 réalisé
